Workbook

Sheet 说明
A1: 大成都青少年足球培训机构数据库
A2: 版本 v0.2 · 编制：2026-10 · 青训相关机构 138 条 · 足球场馆 100 处
A4: 统计年份 | B4: 2026 | C4: ← 可修改的参数（蓝字黄底）
A5: 大型 · 学员≥ | B5: 500
A6: 大型 · 或教练≥ | B6: 20
A7: 中型 · 学员≥ | B7: 100
A8: 中型 · 或教练≥ | B8: 6
A10: 收录范围 | B10: 成都市 12 区 5 市 3 县及高新区、天府新区、东部新区内，开展青少年足球培训的机构：商业培训机构、业余/职业俱乐部青训、海外品牌青训分校、开展青训的协会、提供青少年课程的场馆运营方。连锁品牌按校区分列。
A11: 数据来源 | B11: ① 360地图公开地点检索（按 23 个区县 × 14 个关键词逐一检索，约 340 次查询），取得机构名称、区县、地址、电话；② 活动网（huodong.com）成都足球场馆列表，仅取名称、区县、地址，不采用其页面上的通用性价格/教练描述；③ 公开网页检索（新闻、百科、机构官网、教育宝等）补充成立年份、教练、学员、荣誉、风险信息。每条均附来源。
A12: 重要限制 | B12: 大众点评、美团、抖音、小红书需要登录或有人机验证，企查查/天眼查有反爬验证，成都市体育局网站拒绝访问——本库未绕过这些限制，因此平台评分、评价数、参保人数基本缺失；地图收录的机构中，部分可能是成人业余球队或单纯场地，已在“青训业务”列标注“待核实”。标黄单元格为待采集字段。
A13: 青训业务 | B13: 已证实（有来源）= 来源明确提到青少年培训/梯队；名称显示青少年业务 = 名称含少儿/青训/学院等，待核实；待核实 = 仅地图收录、名称未体现青少年业务，可能为成人业余球队；协会 = 区县足协等。
A14: 零编造原则 | B14: 所有数值均来自所附来源；来源未写明的一律留空，未做任何估算。
A15: 运营年限 | B15: 公式 = 统计年份 − 成立年份（成立年份为空时留空）。
A16: 规模等级 | B16: 公式：学员数或教练员数达到上方阈值即判为大型/中型，否则小型；两项都为空时留空。阈值可在本页 B5–B8 修改。
A17: 可信度 | B17: 高 = 官方或权威媒体来源且信息一致；中 = 单一媒体/机构自述；低 = 信息零散或可能已变更，需电话核实。
A18: 运营状态 | B18: 运营中 = 近年来源显示在运营；现状未知 = 仅有较早资料；规划（未见运营）；已停业（保留作风险提示）；待核实 = 来源未说明。
A19: 数据时效 | B19: 部分数值来自较早年份的报道（已在“规模说明/备注”中注明年份），使用前请核实。
A21: 建议补采路径 | B21: ① 成都市及各区体育局官网《校外体育培训机构白名单》，最权威、最全的名录来源；② 大众点评/美团搜索“青少年足球”“儿童足球”，按区筛选，记录评分、评价数、地址、电话；③ 抖音/小红书搜索机构名，记录粉丝数与口碑；④ 企查查/天眼查查询成立日期、注册资本、参保人数（参保人数可近似反映教练员规模）；⑤ 电话或实地核实学员数。
A22: 表格结构 | B22: 「汇总」按区、按类型统计；「全部机构」为总表（可筛选）；「足球场馆」为可能承接青训课程/赛事的场地（参考）；其后每个区（市县）一张分表。
A25: 图例 | B25: 黄底空白 = 待采集字段

Sheet 汇总
A1: 区（市县） | B1: 合计 | C1: 培训机构 | D1: 业余俱乐部 | E1: 职业俱乐部青训 | F1: 海外青训分校 | G1: 协会 | H1: 场馆运营方 | I1: 其他 | J1: 有电话 | K1: 有成立年份 | L1: 有评分 | M1: 青训已证实
A2: 锦江区 | B2: =COUNTIFS(全部机构!$B$2:$B$139,$A2) -> 10 | C2: =COUNTIFS(全部机构!$B$2:$B$139,$A2,全部机构!$E$2:$E$139,"培训机构") -> 4 | D2: =COUNTIFS(全部机构!$B$2:$B$139,$A2,全部机构!$E$2:$E$139,"业余俱乐部") -> 5 | E2: =COUNTIFS(全部机构!$B$2:$B$139,$A2,全部机构!$E$2:$E$139,"职业俱乐部青训") -> 1 | F2: =COUNTIFS(全部机构!$B$2:$B$139,$A2,全部机构!$E$2:$E$139,"海外青训分校") -> 0 | G2: =COUNTIFS(全部机构!$B$2:$B$139,$A2,全部机构!$E$2:$E$139,"协会") -> 0 | H2: =COUNTIFS(全部机构!$B$2:$B$139,$A2,全部机构!$E$2:$E$139,"场馆运营方") -> 0 | I2: =COUNTIFS(全部机构!$B$2:$B$139,$A2,全部机构!$E$2:$E$139,"其他") -> 0 | J2: =COUNTIFS(全部机构!$B$2:$B$139,$A2,全部机构!$J$2:$J$139,"<>") -> 5 | K2: =COUNTIFS(全部机构!$B$2:$B$139,$A2,全部机构!$L$2:$L$139,"<>") -> 1 | L2: =COUNTIFS(全部机构!$B$2:$B$139,$A2,全部机构!$U$2:$U$139,"<>")+COUNTIFS(全部机构!$B$2:$B$139,$A2,全部机构!$V$2:$V$139,"<>")+COUNTIFS(全部机构!$B$2:$B$139,$A2,全部机构!$W$2:$W$139,"<>") -> 1 | M2: =COUNTIFS(全部机构!$B$2:$B$139,$A2,全部机构!$F$2:$F$139,"已证实（有来源）") -> 3
A3: 青羊区 | B3: =COUNTIFS(全部机构!$B$2:$B$139,$A3) -> 9 | C3: =COUNTIFS(全部机构!$B$2:$B$139,$A3,全部机构!$E$2:$E$139,"培训机构") -> 3 | D3: =COUNTIFS(全部机构!$B$2:$B$139,$A3,全部机构!$E$2:$E$139,"业余俱乐部") -> 4 | E3: =COUNTIFS(全部机构!$B$2:$B$139,$A3,全部机构!$E$2:$E$139,"职业俱乐部青训") -> 0 | F3: =COUNTIFS(全部机构!$B$2:$B$139,$A3,全部机构!$E$2:$E$139,"海外青训分校") -> 0 | G3: =COUNTIFS(全部机构!$B$2:$B$139,$A3,全部机构!$E$2:$E$139,"协会") -> 0 | H3: =COUNTIFS(全部机构!$B$2:$B$139,$A3,全部机构!$E$2:$E$139,"场馆运营方") -> 2 | I3: =COUNTIFS(全部机构!$B$2:$B$139,$A3,全部机构!$E$2:$E$139,"其他") -> 0 | J3: =COUNTIFS(全部机构!$B$2:$B$139,$A3,全部机构!$J$2:$J$139,"<>") -> 3 | K3: =COUNTIFS(全部机构!$B$2:$B$139,$A3,全部机构!$L$2:$L$139,"<>") -> 1 | L3: =COUNTIFS(全部机构!$B$2:$B$139,$A3,全部机构!$U$2:$U$139,"<>")+COUNTIFS(全部机构!$B$2:$B$139,$A3,全部机构!$V$2:$V$139,"<>")+COUNTIFS(全部机构!$B$2:$B$139,$A3,全部机构!$W$2:$W$139,"<>") -> 0 | M3: =COUNTIFS(全部机构!$B$2:$B$139,$A3,全部机构!$F$2:$F$139,"已证实（有来源）") -> 4
A4: 金牛区 | B4: =COUNTIFS(全部机构!$B$2:$B$139,$A4) -> 6 | C4: =COUNTIFS(全部机构!$B$2:$B$139,$A4,全部机构!$E$2:$E$139,"培训机构") -> 3 | D4: =COUNTIFS(全部机构!$B$2:$B$139,$A4,全部机构!$E$2:$E$139,"业余俱乐部") -> 2 | E4: =COUNTIFS(全部机构!$B$2:$B$139,$A4,全部机构!$E$2:$E$139,"职业俱乐部青训") -> 0 | F4: =COUNTIFS(全部机构!$B$2:$B$139,$A4,全部机构!$E$2:$E$139,"海外青训分校") -> 0 | G4: =COUNTIFS(全部机构!$B$2:$B$139,$A4,全部机构!$E$2:$E$139,"协会") -> 1 | H4: =COUNTIFS(全部机构!$B$2:$B$139,$A4,全部机构!$E$2:$E$139,"场馆运营方") -> 0 | I4: =COUNTIFS(全部机构!$B$2:$B$139,$A4,全部机构!$E$2:$E$139,"其他") -> 0 | J4: =COUNTIFS(全部机构!$B$2:$B$139,$A4,全部机构!$J$2:$J$139,"<>") -> 0 | K4: =COUNTIFS(全部机构!$B$2:$B$139,$A4,全部机构!$L$2:$L$139,"<>") -> 0 | L4: =COUNTIFS(全部机构!$B$2:$B$139,$A4,全部机构!$U$2:$U$139,"<>")+COUNTIFS(全部机构!$B$2:$B$139,$A4,全部机构!$V$2:$V$139,"<>")+COUNTIFS(全部机构!$B$2:$B$139,$A4,全部机构!$W$2:$W$139,"<>") -> 0 | M4: =COUNTIFS(全部机构!$B$2:$B$139,$A4,全部机构!$F$2:$F$139,"已证实（有来源）") -> 3
A5: 武侯区 | B5: =COUNTIFS(全部机构!$B$2:$B$139,$A5) -> 14 | C5: =COUNTIFS(全部机构!$B$2:$B$139,$A5,全部机构!$E$2:$E$139,"培训机构") -> 6 | D5: =COUNTIFS(全部机构!$B$2:$B$139,$A5,全部机构!$E$2:$E$139,"业余俱乐部") -> 7 | E5: =COUNTIFS(全部机构!$B$2:$B$139,$A5,全部机构!$E$2:$E$139,"职业俱乐部青训") -> 0 | F5: =COUNTIFS(全部机构!$B$2:$B$139,$A5,全部机构!$E$2:$E$139,"海外青训分校") -> 0 | G5: =COUNTIFS(全部机构!$B$2:$B$139,$A5,全部机构!$E$2:$E$139,"协会") -> 0 | H5: =COUNTIFS(全部机构!$B$2:$B$139,$A5,全部机构!$E$2:$E$139,"场馆运营方") -> 1 | I5: =COUNTIFS(全部机构!$B$2:$B$139,$A5,全部机构!$E$2:$E$139,"其他") -> 0 | J5: =COUNTIFS(全部机构!$B$2:$B$139,$A5,全部机构!$J$2:$J$139,"<>") -> 4 | K5: =COUNTIFS(全部机构!$B$2:$B$139,$A5,全部机构!$L$2:$L$139,"<>") -> 3 | L5: =COUNTIFS(全部机构!$B$2:$B$139,$A5,全部机构!$U$2:$U$139,"<>")+COUNTIFS(全部机构!$B$2:$B$139,$A5,全部机构!$V$2:$V$139,"<>")+COUNTIFS(全部机构!$B$2:$B$139,$A5,全部机构!$W$2:$W$139,"<>") -> 0 | M5: =COUNTIFS(全部机构!$B$2:$B$139,$A5,全部机构!$F$2:$F$139,"已证实（有来源）") -> 3
A6: 成华区 | B6: =COUNTIFS(全部机构!$B$2:$B$139,$A6) -> 8 | C6: =COUNTIFS(全部机构!$B$2:$B$139,$A6,全部机构!$E$2:$E$139,"培训机构") -> 2 | D6: =COUNTIFS(全部机构!$B$2:$B$139,$A6,全部机构!$E$2:$E$139,"业余俱乐部") -> 6 | E6: =COUNTIFS(全部机构!$B$2:$B$139,$A6,全部机构!$E$2:$E$139,"职业俱乐部青训") -> 0 | F6: =COUNTIFS(全部机构!$B$2:$B$139,$A6,全部机构!$E$2:$E$139,"海外青训分校") -> 0 | G6: =COUNTIFS(全部机构!$B$2:$B$139,$A6,全部机构!$E$2:$E$139,"协会") -> 0 | H6: =COUNTIFS(全部机构!$B$2:$B$139,$A6,全部机构!$E$2:$E$139,"场馆运营方") -> 0 | I6: =COUNTIFS(全部机构!$B$2:$B$139,$A6,全部机构!$E$2:$E$139,"其他") -> 0 | J6: =COUNTIFS(全部机构!$B$2:$B$139,$A6,全部机构!$J$2:$J$139,"<>") -> 3 | K6: =COUNTIFS(全部机构!$B$2:$B$139,$A6,全部机构!$L$2:$L$139,"<>") -> 0 | L6: =COUNTIFS(全部机构!$B$2:$B$139,$A6,全部机构!$U$2:$U$139,"<>")+COUNTIFS(全部机构!$B$2:$B$139,$A6,全部机构!$V$2:$V$139,"<>")+COUNTIFS(全部机构!$B$2:$B$139,$A6,全部机构!$W$2:$W$139,"<>") -> 1 | M6: =COUNTIFS(全部机构!$B$2:$B$139,$A6,全部机构!$F$2:$F$139,"已证实（有来源）") -> 2
A7: 高新区 | B7: =COUNTIFS(全部机构!$B$2:$B$139,$A7) -> 5 | C7: =COUNTIFS(全部机构!$B$2:$B$139,$A7,全部机构!$E$2:$E$139,"培训机构") -> 4 | D7: =COUNTIFS(全部机构!$B$2:$B$139,$A7,全部机构!$E$2:$E$139,"业余俱乐部") -> 0 | E7: =COUNTIFS(全部机构!$B$2:$B$139,$A7,全部机构!$E$2:$E$139,"职业俱乐部青训") -> 0 | F7: =COUNTIFS(全部机构!$B$2:$B$139,$A7,全部机构!$E$2:$E$139,"海外青训分校") -> 1 | G7: =COUNTIFS(全部机构!$B$2:$B$139,$A7,全部机构!$E$2:$E$139,"协会") -> 0 | H7: =COUNTIFS(全部机构!$B$2:$B$139,$A7,全部机构!$E$2:$E$139,"场馆运营方") -> 0 | I7: =COUNTIFS(全部机构!$B$2:$B$139,$A7,全部机构!$E$2:$E$139,"其他") -> 0 | J7: =COUNTIFS(全部机构!$B$2:$B$139,$A7,全部机构!$J$2:$J$139,"<>") -> 0 | K7: =COUNTIFS(全部机构!$B$2:$B$139,$A7,全部机构!$L$2:$L$139,"<>") -> 0 | L7: =COUNTIFS(全部机构!$B$2:$B$139,$A7,全部机构!$U$2:$U$139,"<>")+COUNTIFS(全部机构!$B$2:$B$139,$A7,全部机构!$V$2:$V$139,"<>")+COUNTIFS(全部机构!$B$2:$B$139,$A7,全部机构!$W$2:$W$139,"<>") -> 0 | M7: =COUNTIFS(全部机构!$B$2:$B$139,$A7,全部机构!$F$2:$F$139,"已证实（有来源）") -> 4
A8: 天府新区 | B8: =COUNTIFS(全部机构!$B$2:$B$139,$A8) -> 9 | C8: =COUNTIFS(全部机构!$B$2:$B$139,$A8,全部机构!$E$2:$E$139,"培训机构") -> 3 | D8: =COUNTIFS(全部机构!$B$2:$B$139,$A8,全部机构!$E$2:$E$139,"业余俱乐部") -> 3 | E8: =COUNTIFS(全部机构!$B$2:$B$139,$A8,全部机构!$E$2:$E$139,"职业俱乐部青训") -> 1 | F8: =COUNTIFS(全部机构!$B$2:$B$139,$A8,全部机构!$E$2:$E$139,"海外青训分校") -> 1 | G8: =COUNTIFS(全部机构!$B$2:$B$139,$A8,全部机构!$E$2:$E$139,"协会") -> 0 | H8: =COUNTIFS(全部机构!$B$2:$B$139,$A8,全部机构!$E$2:$E$139,"场馆运营方") -> 1 | I8: =COUNTIFS(全部机构!$B$2:$B$139,$A8,全部机构!$E$2:$E$139,"其他") -> 0 | J8: =COUNTIFS(全部机构!$B$2:$B$139,$A8,全部机构!$J$2:$J$139,"<>") -> 0 | K8: =COUNTIFS(全部机构!$B$2:$B$139,$A8,全部机构!$L$2:$L$139,"<>") -> 3 | L8: =COUNTIFS(全部机构!$B$2:$B$139,$A8,全部机构!$U$2:$U$139,"<>")+COUNTIFS(全部机构!$B$2:$B$139,$A8,全部机构!$V$2:$V$139,"<>")+COUNTIFS(全部机构!$B$2:$B$139,$A8,全部机构!$W$2:$W$139,"<>") -> 0 | M8: =COUNTIFS(全部机构!$B$2:$B$139,$A8,全部机构!$F$2:$F$139,"已证实（有来源）") -> 4
A9: 东部新区 | B9: =COUNTIFS(全部机构!$B$2:$B$139,$A9) -> 0 | C9: =COUNTIFS(全部机构!$B$2:$B$139,$A9,全部机构!$E$2:$E$139,"培训机构") -> 0 | D9: =COUNTIFS(全部机构!$B$2:$B$139,$A9,全部机构!$E$2:$E$139,"业余俱乐部") -> 0 | E9: =COUNTIFS(全部机构!$B$2:$B$139,$A9,全部机构!$E$2:$E$139,"职业俱乐部青训") -> 0 | F9: =COUNTIFS(全部机构!$B$2:$B$139,$A9,全部机构!$E$2:$E$139,"海外青训分校") -> 0 | G9: =COUNTIFS(全部机构!$B$2:$B$139,$A9,全部机构!$E$2:$E$139,"协会") -> 0 | H9: =COUNTIFS(全部机构!$B$2:$B$139,$A9,全部机构!$E$2:$E$139,"场馆运营方") -> 0 | I9: =COUNTIFS(全部机构!$B$2:$B$139,$A9,全部机构!$E$2:$E$139,"其他") -> 0 | J9: =COUNTIFS(全部机构!$B$2:$B$139,$A9,全部机构!$J$2:$J$139,"<>") -> 0 | K9: =COUNTIFS(全部机构!$B$2:$B$139,$A9,全部机构!$L$2:$L$139,"<>") -> 0 | L9: =COUNTIFS(全部机构!$B$2:$B$139,$A9,全部机构!$U$2:$U$139,"<>")+COUNTIFS(全部机构!$B$2:$B$139,$A9,全部机构!$V$2:$V$139,"<>")+COUNTIFS(全部机构!$B$2:$B$139,$A9,全部机构!$W$2:$W$139,"<>") -> 0 | M9: =COUNTIFS(全部机构!$B$2:$B$139,$A9,全部机构!$F$2:$F$139,"已证实（有来源）") -> 0
A10: 龙泉驿区 | B10: =COUNTIFS(全部机构!$B$2:$B$139,$A10) -> 6 | C10: =COUNTIFS(全部机构!$B$2:$B$139,$A10,全部机构!$E$2:$E$139,"培训机构") -> 0 | D10: =COUNTIFS(全部机构!$B$2:$B$139,$A10,全部机构!$E$2:$E$139,"业余俱乐部") -> 5 | E10: =COUNTIFS(全部机构!$B$2:$B$139,$A10,全部机构!$E$2:$E$139,"职业俱乐部青训") -> 0 | F10: =COUNTIFS(全部机构!$B$2:$B$139,$A10,全部机构!$E$2:$E$139,"海外青训分校") -> 0 | G10: =COUNTIFS(全部机构!$B$2:$B$139,$A10,全部机构!$E$2:$E$139,"协会") -> 1 | H10: =COUNTIFS(全部机构!$B$2:$B$139,$A10,全部机构!$E$2:$E$139,"场馆运营方") -> 0 | I10: =COUNTIFS(全部机构!$B$2:$B$139,$A10,全部机构!$E$2:$E$139,"其他") -> 0 | J10: =COUNTIFS(全部机构!$B$2:$B$139,$A10,全部机构!$J$2:$J$139,"<>") -> 0 | K10: =COUNTIFS(全部机构!$B$2:$B$139,$A10,全部机构!$L$2:$L$139,"<>") -> 1 | L10: =COUNTIFS(全部机构!$B$2:$B$139,$A10,全部机构!$U$2:$U$139,"<>")+COUNTIFS(全部机构!$B$2:$B$139,$A10,全部机构!$V$2:$V$139,"<>")+COUNTIFS(全部机构!$B$2:$B$139,$A10,全部机构!$W$2:$W$139,"<>") -> 0 | M10: =COUNTIFS(全部机构!$B$2:$B$139,$A10,全部机构!$F$2:$F$139,"已证实（有来源）") -> 1
A11: 青白江区 | B11: =COUNTIFS(全部机构!$B$2:$B$139,$A11) -> 1 | C11: =COUNTIFS(全部机构!$B$2:$B$139,$A11,全部机构!$E$2:$E$139,"培训机构") -> 0 | D11: =COUNTIFS(全部机构!$B$2:$B$139,$A11,全部机构!$E$2:$E$139,"业余俱乐部") -> 0 | E11: =COUNTIFS(全部机构!$B$2:$B$139,$A11,全部机构!$E$2:$E$139,"职业俱乐部青训") -> 0 | F11: =COUNTIFS(全部机构!$B$2:$B$139,$A11,全部机构!$E$2:$E$139,"海外青训分校") -> 0 | G11: =COUNTIFS(全部机构!$B$2:$B$139,$A11,全部机构!$E$2:$E$139,"协会") -> 1 | H11: =COUNTIFS(全部机构!$B$2:$B$139,$A11,全部机构!$E$2:$E$139,"场馆运营方") -> 0 | I11: =COUNTIFS(全部机构!$B$2:$B$139,$A11,全部机构!$E$2:$E$139,"其他") -> 0 | J11: =COUNTIFS(全部机构!$B$2:$B$139,$A11,全部机构!$J$2:$J$139,"<>") -> 0 | K11: =COUNTIFS(全部机构!$B$2:$B$139,$A11,全部机构!$L$2:$L$139,"<>") -> 0 | L11: =COUNTIFS(全部机构!$B$2:$B$139,$A11,全部机构!$U$2:$U$139,"<>")+COUNTIFS(全部机构!$B$2:$B$139,$A11,全部机构!$V$2:$V$139,"<>")+COUNTIFS(全部机构!$B$2:$B$139,$A11,全部机构!$W$2:$W$139,"<>") -> 0 | M11: =COUNTIFS(全部机构!$B$2:$B$139,$A11,全部机构!$F$2:$F$139,"已证实（有来源）") -> 0
A12: 新都区 | B12: =COUNTIFS(全部机构!$B$2:$B$139,$A12) -> 6 | C12: =COUNTIFS(全部机构!$B$2:$B$139,$A12,全部机构!$E$2:$E$139,"培训机构") -> 2 | D12: =COUNTIFS(全部机构!$B$2:$B$139,$A12,全部机构!$E$2:$E$139,"业余俱乐部") -> 4 | E12: =COUNTIFS(全部机构!$B$2:$B$139,$A12,全部机构!$E$2:$E$139,"职业俱乐部青训") -> 0 | F12: =COUNTIFS(全部机构!$B$2:$B$139,$A12,全部机构!$E$2:$E$139,"海外青训分校") -> 0 | G12: =COUNTIFS(全部机构!$B$2:$B$139,$A12,全部机构!$E$2:$E$139,"协会") -> 0 | H12: =COUNTIFS(全部机构!$B$2:$B$139,$A12,全部机构!$E$2:$E$139,"场馆运营方") -> 0 | I12: =COUNTIFS(全部机构!$B$2:$B$139,$A12,全部机构!$E$2:$E$139,"其他") -> 0 | J12: =COUNTIFS(全部机构!$B$2:$B$139,$A12,全部机构!$J$2:$J$139,"<>") -> 1 | K12: =COUNTIFS(全部机构!$B$2:$B$139,$A12,全部机构!$L$2:$L$139,"<>") -> 2 | L12: =COUNTIFS(全部机构!$B$2:$B$139,$A12,全部机构!$U$2:$U$139,"<>")+COUNTIFS(全部机构!$B$2:$B$139,$A12,全部机构!$V$2:$V$139,"<>")+COUNTIFS(全部机构!$B$2:$B$139,$A12,全部机构!$W$2:$W$139,"<>") -> 0 | M12: =COUNTIFS(全部机构!$B$2:$B$139,$A12,全部机构!$F$2:$F$139,"已证实（有来源）") -> 3
A13: 温江区 | B13: =COUNTIFS(全部机构!$B$2:$B$139,$A13) -> 7 | C13: =COUNTIFS(全部机构!$B$2:$B$139,$A13,全部机构!$E$2:$E$139,"培训机构") -> 0 | D13: =COUNTIFS(全部机构!$B$2:$B$139,$A13,全部机构!$E$2:$E$139,"业余俱乐部") -> 2 | E13: =COUNTIFS(全部机构!$B$2:$B$139,$A13,全部机构!$E$2:$E$139,"职业俱乐部青训") -> 0 | F13: =COUNTIFS(全部机构!$B$2:$B$139,$A13,全部机构!$E$2:$E$139,"海外青训分校") -> 0 | G13: =COUNTIFS(全部机构!$B$2:$B$139,$A13,全部机构!$E$2:$E$139,"协会") -> 3 | H13: =COUNTIFS(全部机构!$B$2:$B$139,$A13,全部机构!$E$2:$E$139,"场馆运营方") -> 1 | I13: =COUNTIFS(全部机构!$B$2:$B$139,$A13,全部机构!$E$2:$E$139,"其他") -> 1 | J13: =COUNTIFS(全部机构!$B$2:$B$139,$A13,全部机构!$J$2:$J$139,"<>") -> 0 | K13: =COUNTIFS(全部机构!$B$2:$B$139,$A13,全部机构!$L$2:$L$139,"<>") -> 0 | L13: =COUNTIFS(全部机构!$B$2:$B$139,$A13,全部机构!$U$2:$U$139,"<>")+COUNTIFS(全部机构!$B$2:$B$139,$A13,全部机构!$V$2:$V$139,"<>")+COUNTIFS(全部机构!$B$2:$B$139,$A13,全部机构!$W$2:$W$139,"<>") -> 0 | M13: =COUNTIFS(全部机构!$B$2:$B$139,$A13,全部机构!$F$2:$F$139,"已证实（有来源）") -> 1
... A25: 全市/多区 | B25: =COUNTIFS(全部机构!$B$2:$B$139,$A25) -> 14 | C25: =COUNTIFS(全部机构!$B$2:$B$139,$A25,全部机构!$E$2:$E$139,"培训机构") -> 5 | D25: =COUNTIFS(全部机构!$B$2:$B$139,$A25,全部机构!$E$2:$E$139,"业余俱乐部") -> 1 | E25: =COUNTIFS(全部机构!$B$2:$B$139,$A25,全部机构!$E$2:$E$139,"职业俱乐部青训") -> 1 | F25: =COUNTIFS(全部机构!$B$2:$B$139,$A25,全部机构!$E$2:$E$139,"海外青训分校") -> 4 | G25: =COUNTIFS(全部机构!$B$2:$B$139,$A25,全部机构!$E$2:$E$139,"协会") -> 2 | H25: =COUNTIFS(全部机构!$B$2:$B$139,$A25,全部机构!$E$2:$E$139,"场馆运营方") -> 0 | I25: =COUNTIFS(全部机构!$B$2:$B$139,$A25,全部机构!$E$2:$E$139,"其他") -> 1 | J25: =COUNTIFS(全部机构!$B$2:$B$139,$A25,全部机构!$J$2:$J$139,"<>") -> 0 | K25: =COUNTIFS(全部机构!$B$2:$B$139,$A25,全部机构!$L$2:$L$139,"<>") -> 6 | L25: =COUNTIFS(全部机构!$B$2:$B$139,$A25,全部机构!$U$2:$U$139,"<>")+COUNTIFS(全部机构!$B$2:$B$139,$A25,全部机构!$V$2:$V$139,"<>")+COUNTIFS(全部机构!$B$2:$B$139,$A25,全部机构!$W$2:$W$139,"<>") -> 0 | M25: =COUNTIFS(全部机构!$B$2:$B$139,$A25,全部机构!$F$2:$F$139,"已证实（有来源）") -> 11
A26: 合计 | B26: =SUM(B2:B25) -> 138 | C26: =SUM(C2:C25) -> 41 | D26: =SUM(D2:D25) -> 54 | E26: =SUM(E2:E25) -> 4 | F26: =SUM(F2:F25) -> 6 | G26: =SUM(G2:G25) -> 17 | H26: =SUM(H2:H25) -> 9 | I26: =SUM(I2:I25) -> 7 | ... M26: =SUM(M2:M25) -> 49
A28: 注：类型以来源描述归类；“有电话/有成立年份/有评分”用于显示各区信息完整度。

Sheet 全部机构
A1: 序号 | B1: 区（市县） | C1: 机构名称 | D1: 品牌/所属 | E1: 机构类型 | F1: 青训业务 | G1: 运营状态 | H1: 公司/法人名称 | I1: 训练地址 | J1: 联系电话 | K1: 其他联系方式 | L1: 成立年份 | M1: 运营年限（年） | N1: 运营年限说明 | O1: 教练员数量 | P1: 学员数量 | Q1: 校区/场地数 | R1: 规模等级 | S1: 规模说明 | T1: 招生年龄 | U1: 大众点评评分 | V1: 美团评分 | W1: 其他平台评分 | X1: 收费信息 | Y1: 荣誉/资质 | Z1: 信息来源 | AA1: 可信度 | AB1: 待核实/备注
A2: 1 | B2: 锦江区 | C2: 四川省宇晖仁德足球俱乐部（卡尔美·成都仁德足球青训基地） | D2: 仁德足球 | E2: 业余俱乐部 | F2: 已证实（有来源） | G2: 待核实 | H2: 四川省宇晖仁德体育文化传播有限责任公司（关联待确认） | I2: 三环路东一段附近 | J2: +86-15114062861 | K2: 官网 http://www.yhrdty.com | L2: 2015 | M2: =IF(L2="","",说明!$B$4-L2) -> 11 | N2: 公司2015-03-05成立（企查查）；注册资本200万元；法定代表人马明宇 | P2: 200 | Q2: 卡尔美成都仁德足球青训基地；锦江仁德足球主题公园 | R2: =IF(AND(P2="",O2=""),"",IF(OR(N(P2)>=说明!$B$5,N(O2)>=说明!$B$6),"大型",IF(OR(N(P2)>=说明!$B$7,N(O2)>=说明!$B$8),"中型","小型"))) -> 中型 | S2: 向锦江、成华、武侯等区学校派驻教练；长期学员约200名（百度百科，年份未注明）；拥有14块标准场地（四川省体育局2020年报道） | T2: 4–18岁 | Y2: 2018雪佛兰全国少儿足球冠军赛成都赛区冠军 | Z2: http://www.yhrdty.com/index.php?m=content&c=index&a=lists&catid=19 https://www.thecfa.cn/cgzq/20190114/26088.html 360地图 POI（restapi.map.so.com） https://huodong.com/venue/detail/tktmlk https://m.qcc.com/firm/3bac3d95ecf684438bd98491320d4a5c.html https://tyj.sc.gov.cn/sctyj/TYaddN/2020/9/14/9855f7280b6649d3bcbf0dd0560f9629.shtml https://baike.baidu.com/item/%E5%9B%9B%E5%B7%9D%E5%AE%87%E6%99%96%E4%BB%81%E5%BE%B7%E8%B6%B3%E7%90%83%E4%BF%B1%E4%B9%90%E9%83%A8/64016151 | AA2: 中 | AB2: 所在区为推断
A3: 2 | B3: 锦江区 | C3: 之己体育迈浪足球学院（锦江店） | D3: 之己体育 / 迈浪足球 | E3: 培训机构 | F3: 已证实（有来源） | G3: 待核实 | I3: 锦江区动感熊猫体育公园内 | J3: 18980068009 | M3: =IF(L3="","",说明!$B$4-L3) | Q3: 锦江店 | R3: =IF(AND(P3="",O3=""),"",IF(OR(N(P3)>=说明!$B$5,N(O3)>=说明!$B$6),"大型",IF(OR(N(P3)>=说明!$B$7,N(O3)>=说明!$B$8),"中型","小型"))) | S3: 5人制、7人制人造草场地 | Z3: https://huodong.com/venue/detail/eyLaq https://huodong.com/venue/detail/qhispx | AA3: 低
A4: 3 | B4: 锦江区 | C4: 索福德青少儿快乐足球培训 | D4: 索福德 | E4: 培训机构 | F4: 已证实（有来源） | G4: 待核实 | I4: 锦江区晨辉西路56号足球公园园区内 | K4: 网站 soccerworld.cn | M4: =IF(L4="","",说明!$B$4-L4) | Q4: 锦江区晨辉西路56号足球公园园区内配套1号办公房屋 | R4: =IF(AND(P4="",O4=""),"",IF(OR(N(P4)>=说明!$B$5,N(O4)>=说明!$B$6),"大型",IF(OR(N(P4)>=说明!$B$7,N(O4)>=说明!$B$8),"中型","小型"))) | W4: 3.0（教育宝（口碑值）） | Z4: https://cd.jiaoyubao.cn/zuqiu/ https://s.jiaoyubao.cn/do/?c=cd&classename=qiulei&k=%E5%B0%91%E5%84%BF | AA4: 低
A5: 4 | B5: 锦江区 | C5: 大牛青少年足球俱乐部 | D5: 大牛青少年足球俱乐部 | E5: 业余俱乐部 | F5: 名称显示青少年业务（待核实） | G5: 运营中（平台收录） | M5: =IF(L5="","",说明!$B$4-L5) | R5: =IF(AND(P5="",O5=""),"",IF(OR(N(P5)>=说明!$B$5,N(O5)>=说明!$B$6),"大型",IF(OR(N(P5)>=说明!$B$7,N(O5)>=说明!$B$8),"中型","小型"))) | Z5: https://huodong.com/venue/detail/yqnohb | AA5: 低
A6: 5 | B6: 锦江区 | C6: 圣斯顿足球俱乐部 | D6: 圣斯顿足球俱乐部 | E6: 业余俱乐部 | F6: 待核实（可能为成人业余球队/场地） | G6: 运营中（平台收录） | M6: =IF(L6="","",说明!$B$4-L6) | R6: =IF(AND(P6="",O6=""),"",IF(OR(N(P6)>=说明!$B$5,N(O6)>=说明!$B$6),"大型",IF(OR(N(P6)>=说明!$B$7,N(O6)>=说明!$B$8),"中型","小型"))) | Z6: https://huodong.com/venue/detail/zbwuqj | AA6: 低
A7: 6 | B7: 锦江区 | C7: 天际线足球俱乐部 | D7: 天际线足球俱乐部 | E7: 业余俱乐部 | F7: 待核实（可能为成人业余球队/场地） | G7: 运营中（地图收录） | I7: 成都市锦江区琉新路301号 | J7: 18628004621 | M7: =IF(L7="","",说明!$B$4-L7) | R7: =IF(AND(P7="",O7=""),"",IF(OR(N(P7)>=说明!$B$5,N(O7)>=说明!$B$6),"大型",IF(OR(N(P7)>=说明!$B$7,N(O7)>=说明!$B$8),"中型","小型"))) | Z7: 360地图 POI（restapi.map.so.com） | AA7: 中
A8: 7 | B8: 锦江区 | C8: 跃九天足球俱乐部 | D8: 跃九天足球俱乐部 | E8: 业余俱乐部 | F8: 待核实（可能为成人业余球队/场地） | G8: 运营中（平台收录） | M8: =IF(L8="","",说明!$B$4-L8) | R8: =IF(AND(P8="",O8=""),"",IF(OR(N(P8)>=说明!$B$5,N(O8)>=说明!$B$6),"大型",IF(OR(N(P8)>=说明!$B$7,N(O8)>=说明!$B$8),"中型","小型"))) | Z8: https://huodong.com/venue/detail/rdcpde | AA8: 低
A9: 8 | B9: 锦江区 | C9: 众禾足球俱乐部 | D9: 众禾足球 | E9: 培训机构 | F9: 待核实（来源未证实青训业务） | G9: 待核实 | I9: 锦江区 众禾双桥子足球公园（环球汇·天誉）；另见静思南巷与中环路锦绣大道段交叉口 | M9: =IF(L9="","",说明!$B$4-L9) | R9: =IF(AND(P9="",O9=""),"",IF(OR(N(P9)>=说明!$B$5,N(O9)>=说明!$B$6),"大型",IF(OR(N(P9)>=说明!$B$7,N(O9)>=说明!$B$8),"中型","小型"))) | S9: 参加第一届中国青少年足球联赛（四川赛区）U9并小组出线；场地地图列有“众禾双桥子足球公园”（关系未证实） | X9: 周末班、寒暑假集训 | Z9: https://huodong.com/venue/detail/eyLaA https://sichuan.scol.com.cn/ggxw/202302/58806642.html https://cd.jiaoyubao.cn/zuqiu/dt_z1910.html | AA9: 中 | AB9: 教育宝：暂无评分
A10: 9 | B10: 锦江区 | C10: 传奇足球梦工场 | D10: 传奇足球梦工场 | E10: 培训机构 | F10: 待核实（可能为成人业余球队/场地） | G10: 运营中（地图收录） | I10: 成都市锦江区桦彩路89号 | J10: 028-61112170 | M10: =IF(L10="","",说明!$B$4-L10) | R10: =IF(AND(P10="",O10=""),"",IF(OR(N(P10)>=说明!$B$5,N(O10)>=说明!$B$6),"大型",IF(OR(N(P10)>=说明!$B$7,N(O10)>=说明!$B$8),"中型","小型"))) | Z10: 360地图 POI（restapi.map.so.com） | AA10: 中
A11: 10 | B11: 锦江区 | C11: 绿轴兴城足球公园(训练基地) | D11: 绿轴兴城足球公园 | E11: 职业俱乐部青训 | F11: 待核实（可能为成人业余球队/场地） | G11: 运营中（地图收录） | I11: 成都市锦江区首开龙湖天璞东门东北 | J11: 18512871289 | M11: =IF(L11="","",说明!$B$4-L11) | R11: =IF(AND(P11="",O11=""),"",IF(OR(N(P11)>=说明!$B$5,N(O11)>=说明!$B$6),"大型",IF(OR(N(P11)>=说明!$B$7,N(O11)>=说明!$B$8),"中型","小型"))) | Z11: 360地图 POI（restapi.map.so.com） | AA11: 中 | AB11: 成都蓉城足球俱乐部训练基地（地图名称），是否对外开设青少年课程未知
A12: 11 | B12: 青羊区 | C12: 皇家贝里斯足球俱乐部（皇贝青训） | D12: 皇贝 | E12: 业余俱乐部 | F12: 已证实（有来源） | G12: 待核实 | I12: 青羊区贝森北路西村大院 | J12: 18080802014 | L12: 2013 | M12: =IF(L12="","",说明!$B$4-L12) -> 13 | N12: 百科称2013年底创立（另说2014年）；运营公司2016年5月成立 | P12: 5000 | Q12: 西村、光华、清波、桂溪、晨辉 5个校区（百度百科）；青羊区贝森北路1号西村大院 | R12: =IF(AND(P12="",O12=""),"",IF(OR(N(P12)>=说明!$B$5,N(O12)>=说明!$B$6),"大型",IF(OR(N(P12)>=说明!$B$7,N(O12)>=说明!$B$8),"中型","小型"))) -> 大型 | S12: 多支6–12岁梯队及兴趣班；累计学员5000余名（百度百科，2025）；约2017年调查：教练10余名 | T12: 6–12岁梯队 | X12: 较早调查：寒假班1280元（年份未标注） | Y12: 据称2019年获中国足协“全国社会足球品牌青训机构”认定（四川唯一）；青训总教练持亚足联A级；青训总教练张林海（原成都五牛主帅） | Z12: https://www.sohu.com/a/338252396_120288288 https://baike.baidu.com/item/%E7%9A%87%E5%AE%B6%E8%B4%9D%E9%87%8C%E6%96%AF%E8%B6%B3%E7%90%83%E4%BF%B1%E4%B9%90%E9%83%A8/16686556 https://m.dongqiudi.com/article/2144123.html 360地图 POI（restapi.map.so.com） http://www.dianping.com/shop/25035403/photos?pg=17 | AA12: 中 | AB12: 有门店页（西村校区），评分未显示
A13: 12 | B13: 青羊区 | C13: FF体育公园（FF足球公园 · 成都足协青少年足球培训中心） | D13: FF体育公园 / 成都足协 | E13: 场馆运营方 | F13: 已证实（有来源） | G13: 运营中 | I13: 成都市青羊区光华大道一段（万家湾公交总站旁） | J13: 028-86743798 | K13: 电话见中国足协官网成都青训中心页面 | M13: =IF(L13="","",说明!$B$4-L13) | Q13: 地图收录：FF足球公园卡丁车俱乐部（青羊区）成都市青羊区蔡桥街道光华8线与成飞大道交汇处万家福地西南角；地图收录：国家青少年足球训练中心（青羊区）成都市青羊区光华南三路88号正西方向180米 | R13: =IF(AND(P13="",O13=""),"",IF(OR(N(P13)>=说明!$B$5,N(O13)>=说明!$B$6),"大型",IF(OR(N(P13)>=说明!$B$7,N(O13)>=说明!$B$8),"中型","小型"))) | S13: 约80亩、投资约1.3亿元；5块五人制、4块八人制、2块十一人制场地；成都足协挂牌青少年足球培训中心、足球重点项目训练基地 | Y13: 中国足协2026年确定成都为大区青训中心（13–15岁，覆盖西南）；拉玛足球在此设校区 | Z13: https://www.thecfa.cn/qxunzx/20180903/24556.html https://m.dongqiudi.com/article/1654210.html https://sports.sina.cn/2026-08-18/detail-ininswmx7436499.d.html?vt=4 360地图 POI（restapi.map.so.com） | AA13: 中 | AB13: 电话为中国足协页面所列青训中心电话，数据时间较早；地图另列名称：国家青少年足球训练中心（青羊区）
A14: 13 | B14: 青羊区 | C14: 拉玛足球 · 青羊区校区（优品道、FF体育公园） | D14: 拉玛足球 | E14: 培训机构 | F14: 已证实（有来源） | G14: 待核实 | I14: 优品道：青羊大道99号优品广场；FF体育公园：光华大道一段 | M14: =IF(L14="","",说明!$B$4-L14) | Q14: 地图收录：成都拉玛足球俱乐部（青羊区）成都市青羊区青羊大道99号附1优品道广场4F | R14: =IF(AND(P14="",O14=""),"",IF(OR(N(P14)>=说明!$B$5,N(O14)>=说明!$B$6),"大型",IF(OR(N(P14)>=说明!$B$7,N(O14)>=说明!$B$8),"中型","小型"))) | Z14: https://m.youkee.com/xuexiao/lmzq_xiaoqu.html 360地图 POI（restapi.map.so.com） | AA14: 低
A15: 14 | B15: 青羊区 | C15: 花香青少年足球（青羊校区） | D15: 花香 | E15: 培训机构 | F15: 已证实（有来源） | G15: 风险：现状未知 | I15: 青羊区蜀辉路金沙国际商城 | M15: =IF(L15="","",说明!$B$4-L15) | R15: =IF(AND(P15="",O15=""),"",IF(OR(N(P15)>=说明!$B$5,N(O15)>=说明!$B$6),"大型",IF(OR(N(P15)>=说明!$B$7,N(O15)>=说明!$B$8),"中型","小型"))) | T15: 5–14岁 | Z15: https://m.youkee.com/kecheng/11810.html | AA15: 低 | AB15: 品牌母公司2024年北京闭店风波，见“花香盛世体育（品牌）”
A16: 15 | B16: 青羊区 | C16: 中达舒弘青少年足球运动俱乐部(光华校区) | D16: 中达舒弘青少年足球运动俱乐部 | E16: 业余俱乐部 | F16: 名称显示青少年业务（待核实） | G16: 运营中（平台收录） | M16: =IF(L16="","",说明!$B$4-L16) | R16: =IF(AND(P16="",O16=""),"",IF(OR(N(P16)>=说明!$B$5,N(O16)>=说明!$B$6),"大型",IF(OR(N(P16)>=说明!$B$7,N(O16)>=说明!$B$8),"中型","小型"))) | Z16: https://huodong.com/venue/detail/hylemk | AA16: 低
A17: 16 | B17: 青羊区 | C17: 青羊区青少年足球训练基地 | D17: 青羊区青少年足球训练基地 | E17: 培训机构 | F17: 名称显示青少年业务（待核实） | G17: 运营中（平台收录） | M17: =IF(L17="","",说明!$B$4-L17) | R17: =IF(AND(P17="",O17=""),"",IF(OR(N(P17)>=说明!$B$5,N(O17)>=说明!$B$6),"大型",IF(OR(N(P17)>=说明!$B$7,N(O17)>=说明!$B$8),"中型","小型"))) | Z17: https://huodong.com/venue/detail/oqeogw | AA17: 低
A18: 17 | B18: 青羊区 | C18: 99号球会 | D18: 99号球会 | E18: 业余俱乐部 | F18: 待核实（可能为成人业余球队/场地） | G18: 运营中（地图收录） | I18: 成都市青羊区文家街道文家大道 | M18: =IF(L18="","",说明!$B$4-L18) | R18: =IF(AND(P18="",O18=""),"",IF(OR(N(P18)>=说明!$B$5,N(O18)>=说明!$B$6),"大型",IF(OR(N(P18)>=说明!$B$7,N(O18)>=说明!$B$8),"中型","小型"))) | Z18: 360地图 POI（restapi.map.so.com） | AA18: 中
A19: 18 | B19: 青羊区 | C19: 金鹰足球俱乐部 | D19: 金鹰足球俱乐部 | E19: 业余俱乐部 | F19: 待核实（可能为成人业余球队/场地） | G19: 运营中（地图收录） | I19: 成都市青羊区康河街道土龙公路四川商务职业学院东南角 | M19: =IF(L19="","",说明!$B$4-L19) | R19: =IF(AND(P19="",O19=""),"",IF(OR(N(P19)>=说明!$B$5,N(O19)>=说明!$B$6),"大型",IF(OR(N(P19)>=说明!$B$7,N(O19)>=说明!$B$8),"中型","小型"))) | Z19: 360地图 POI（restapi.map.so.com） | AA19: 中
A20: 19 | B20: 青羊区 | C20: 玩湃社区足球公园 | D20: 玩湃社区足球公园 | E20: 场馆运营方 | F20: 待核实（可能为成人业余球队/场地） | G20: 运营中（地图收录） | I20: 成都市青羊区通惠门路37号 | J20: 028-18116599858 | M20: =IF(L20="","",说明!$B$4-L20) | R20: =IF(AND(P20="",O20=""),"",IF(OR(N(P20)>=说明!$B$5,N(O20)>=说明!$B$6),"大型",IF(OR(N(P20)>=说明!$B$7,N(O20)>=说明!$B$8),"中型","小型"))) | S20: 约900㎡，成都首个社区智慧足球公园，设24小时智慧足球课堂 | Z20: 360地图 POI（restapi.map.so.com） https://cbgc.scol.com.cn/news/158341 | AA20: 中
A21: 20 | B21: 金牛区 | C21: 成都大牛体育培训 | D21: 大牛 | E21: 培训机构 | F21: 已证实（有来源） | G21: 待核实 | I21: 成都市金牛区金科苑东街65号1栋5单元1层1号 | M21: =IF(L21="","",说明!$B$4-L21) | R21: =IF(AND(P21="",O21=""),"",IF(OR(N(P21)>=说明!$B$5,N(O21)>=说明!$B$6),"大型",IF(OR(N(P21)>=说明!$B$7,N(O21)>=说明!$B$8),"中型","小型"))) | S21: 教育宝金牛区足球培训列表收录 | Z21: https://cd.jiaoyubao.cn/zuqiu/qu_jinniu.html | AA21: 中 | AB21: 教育宝地址为机构自填，可能已过时
A22: 21 | B22: 金牛区 | C22: 成都杰冠体育培训 | D22: 杰冠 | E22: 培训机构 | F22: 已证实（有来源） | G22: 待核实 | I22: 成都市金牛区天龙大道942号1层 | M22: =IF(L22="","",说明!$B$4-L22) | R22: =IF(AND(P22="",O22=""),"",IF(OR(N(P22)>=说明!$B$5,N(O22)>=说明!$B$6),"大型",IF(OR(N(P22)>=说明!$B$7,N(O22)>=说明!$B$8),"中型","小型"))) | S22: 教育宝金牛区足球培训列表收录 | Z22: https://cd.jiaoyubao.cn/zuqiu/qu_jinniu.html | AA22: 中 | AB22: 教育宝地址为机构自填，可能已过时
A23: 22 | B23: 金牛区 | C23: 拉玛足球 · 花照壁校区 | D23: 拉玛足球 | E23: 培训机构 | F23: 已证实（有来源） | G23: 待核实 | M23: =IF(L23="","",说明!$B$4-L23) | R23: =IF(AND(P23="",O23=""),"",IF(OR(N(P23)>=说明!$B$5,N(O23)>=说明!$B$6),"大型",IF(OR(N(P23)>=说明!$B$7,N(O23)>=说明!$B$8),"中型","小型"))) | Z23: https://m.youkee.com/xiaoqu/7257.html | AA23: 低
A24: 23 | B24: 金牛区 | C24: 金牛区足球协会 | E24: 协会 | F24: 协会（组织/承办青少年赛事） | G24: 待核实 | M24: =IF(L24="","",说明!$B$4-L24) | R24: =IF(AND(P24="",O24=""),"",IF(OR(N(P24)>=说明!$B$5,N(O24)>=说明!$B$6),"大型",IF(OR(N(P24)>=说明!$B$7,N(O24)>=说明!$B$8),"中型","小型"))) | S24: 成都市足协会员协会；未见其直接开展青训的资料。金牛区对社会青训机构实行入库管理和年度星级评定（区校足办负责） | Z24: http://www.lysy90.com/fa/23?local=1 https://www.sport.gov.cn/n20001280/n20745751/n20767239/c21778842/content.html | AA24: 低 | AB24: 金牛区青训机构入库名单值得向区校足办索取
A25: 24 | B25: 金牛区 | C25: 博越足球俱乐部 | D25: 博越足球俱乐部 | E25: 业余俱乐部 | F25: 待核实（可能为成人业余球队/场地） | G25: 运营中（地图收录） | I25: 成都市金牛区金科苑中街与金科苑南街交汇处西南 | M25: =IF(L25="","",说明!$B$4-L25) | R25: =IF(AND(P25="",O25=""),"",IF(OR(N(P25)>=说明!$B$5,N(O25)>=说明!$B$6),"大型",IF(OR(N(P25)>=说明!$B$7,N(O25)>=说明!$B$8),"中型","小型"))) | Z25: 360地图 POI（restapi.map.so.com） | AA25: 中
A26: 25 | B26: 金牛区 | C26: 成都腾飞经典足球俱乐部 | D26: 腾飞经典足球俱乐部 | E26: 业余俱乐部 | F26: 待核实（可能为成人业余球队/场地） | G26: 运营中（平台收录） | M26: =IF(L26="","",说明!$B$4-L26) | R26: =IF(AND(P26="",O26=""),"",IF(OR(N(P26)>=说明!$B$5,N(O26)>=说明!$B$6),"大型",IF(OR(N(P26)>=说明!$B$7,N(O26)>=说明!$B$8),"中型","小型"))) | Z26: https://huodong.com/venue/detail/xcnrnd | AA26: 低
A27: 26 | B27: 武侯区 | C27: 成都贝尔克足球俱乐部 | D27: 贝尔克 | E27: 培训机构 | F27: 已证实（有来源） | G27: 待核实 | L27: 2016 | M27: =IF(L27="","",说明!$B$4-L27) -> 10 | N27: 2016年8月成立（百度百科） | R27: =IF(AND(P27="",O27=""),"",IF(OR(N(P27)>=说明!$B$5,N(O27)>=说明!$B$6),"大型",IF(OR(N(P27)>=说明!$B$7,N(O27)>=说明!$B$8),"中型","小型"))) | S27: 以青少年足球培训为核心的综合素质教育机构，总部在武侯区；百科称教练10余名（含中国足协D级1名）；外籍主教练，称获法国梅斯俱乐部支持 | T27: 4–13岁 | Y27: 华宜天下足球联赛最佳组织奖 | Z27: https://baike.baidu.com/item/%E6%88%90%E9%83%BD%E8%B4%9D%E5%B0%94%E5%85%8B%E8%B6%B3%E7%90%83%E4%BF%B1%E4%B9%90%E9%83%A8/19966520 | AA27: 中
A28: 27 | B28: 武侯区 | C28: 拉玛足球（品牌总部 · 武侯区校区） | D28: 拉玛足球 | E28: 培训机构 | F28: 已证实（有来源） | G28: 运营中（待核实） | I28: 银泰城校区：武侯区益州大道1999号银泰城6楼（总部所在不详，以下为多校区） | J28: 400-666-6886；028-87076722（官网所列）；4006-303-880（聚合平台） | K28: 官网 lamafootball.cn | L28: 2016 | M28: =IF(L28="","",说明!$B$4-L28) -> 10 | N28: 宣传称品牌2016年10月成立 | P28: 550 | Q28: 武侯：银泰城（益州大道1999号6楼）、金楠广场（兆景路199号）、凯德·新南（盛和一路99号）；其他区校区见各区分表 | R28: =IF(AND(P28="",O28=""),"",IF(OR(N(P28)>=说明!$B$5,N(O28)>=说明!$B$6),"大型",IF(OR(N(P28)>=说明!$B$7,N(O28)>=说明!$B$8),"中型","小型"))) -> 大型 | S28: 搜狐较早调查：寒假培训人数由300增至550（年份未标注）；校区数各页不一，一页称8个；聚合平台称员工约50人、办公面积3000㎡（非参保数据） | T28: 4.5–16岁 | Y28: 自述外教来自巴塞罗那；课程分兴趣/提高/精英班 | Z28: https://m.youkee.com/xuexiao/lmzq_xiaoqu.html https://m.youkee.com/xuexiao/lmzq_jianjie.html https://m.sohu.com/n/479553636/?wscrid=95360_1 http://www.lamafootball.cn/nationalCenter/ | AA28: 中 | AB28: 跨武侯/高新/青羊/金牛多区；学员数为某年寒假班人数
A29: 28 | B29: 武侯区 | C29: 胜利联盟菲戈足球学院成都分院 | D29: 胜利联盟/菲戈 | E29: 培训机构 | F29: 已证实（有来源） | G29: 已停业 | I29: 红牌楼某商场顶楼（原址） | M29: =IF(L29="","",说明!$B$4-L29) | R29: =IF(AND(P29="",O29=""),"",IF(OR(N(P29)>=说明!$B$5,N(O29)>=说明!$B$6),"大型",IF(OR(N(P29)>=说明!$B$7,N(O29)>=说明!$B$8),"中型","小型"))) | S29: 2017年报道：停训、人去楼空，家长退费无门 | Z29: https://m.thepaper.cn/wifiKey_detail.jsp?contid=1902798&from=wifiKey https://www.cqcb.com/sports/2017-12-17/600642.html | AA29: 中 | AB29: 保留作风险提示
A30: 29 | B30: 武侯区 | C30: 麒麟小将青训俱乐部 | D30: 麒麟小将青训俱乐部 | E30: 业余俱乐部 | F30: 名称显示青少年业务（待核实） | G30: 运营中（平台收录） | M30: =IF(L30="","",说明!$B$4-L30) | R30: =IF(AND(P30="",O30=""),"",IF(OR(N(P30)>=说明!$B$5,N(O30)>=说明!$B$6),"大型",IF(OR(N(P30)>=说明!$B$7,N(O30)>=说明!$B$8),"中型","小型"))) | Z30: https://huodong.com/venue/detail/otpsba | AA30: 低
A31: 30 | B31: 武侯区 | C31: 斯巴达足球学院(天府四街校区) | D31: 斯巴达足球学院 | E31: 培训机构 | F31: 名称显示青少年业务（待核实） | G31: 运营中（平台收录） | M31: =IF(L31="","",说明!$B$4-L31) | R31: =IF(AND(P31="",O31=""),"",IF(OR(N(P31)>=说明!$B$5,N(O31)>=说明!$B$6),"大型",IF(OR(N(P31)>=说明!$B$7,N(O31)>=说明!$B$8),"中型","小型"))) | Z31: https://huodong.com/venue/detail/xivviu | AA31: 低
A32: 31 | B32: 武侯区 | C32: 909足球俱乐部 | D32: 909足球俱乐部 | E32: 业余俱乐部 | F32: 待核实（可能为成人业余球队/场地） | G32: 运营中（地图收录） | I32: 成都市武侯区东原印长江南侧 | M32: =IF(L32="","",说明!$B$4-L32) | R32: =IF(AND(P32="",O32=""),"",IF(OR(N(P32)>=说明!$B$5,N(O32)>=说明!$B$6),"大型",IF(OR(N(P32)>=说明!$B$7,N(O32)>=说明!$B$8),"中型","小型"))) | Z32: 360地图 POI（restapi.map.so.com） | AA32: 中
A33: 32 | B33: 武侯区 | C33: 富搏足球俱乐部(复城广场店) | D33: 富搏足球俱乐部 | E33: 业余俱乐部 | F33: 待核实（可能为成人业余球队/场地） | G33: 运营中（平台收录） | M33: =IF(L33="","",说明!$B$4-L33) | R33: =IF(AND(P33="",O33=""),"",IF(OR(N(P33)>=说明!$B$5,N(O33)>=说明!$B$6),"大型",IF(OR(N(P33)>=说明!$B$7,N(O33)>=说明!$B$8),"中型","小型"))) | Z33: https://huodong.com/venue/detail/cgbuzm | AA33: 低
A34: 33 | B34: 武侯区 | C34: 富搏足球俱乐部(天府中心店) | D34: 富搏足球俱乐部 | E34: 业余俱乐部 | F34: 待核实（可能为成人业余球队/场地） | G34: 运营中（地图收录） | I34: 成都市武侯区天府一街888号(锦城湖地铁站D口步行160米) | M34: =IF(L34="","",说明!$B$4-L34) | R34: =IF(AND(P34="",O34=""),"",IF(OR(N(P34)>=说明!$B$5,N(O34)>=说明!$B$6),"大型",IF(OR(N(P34)>=说明!$B$7,N(O34)>=说明!$B$8),"中型","小型"))) | Z34: 360地图 POI（restapi.map.so.com） | AA34: 中
A35: 34 | B35: 武侯区 | C35: 成都育英足球俱乐部 | D35: 育英足球俱乐部 | E35: 业余俱乐部 | F35: 待核实（可能为成人业余球队/场地） | G35: 运营中（地图收录） | I35: 成都市武侯区新乐北街10号(四川新北足球中心) | J35: 19828366604 | M35: =IF(L35="","",说明!$B$4-L35) | R35: =IF(AND(P35="",O35=""),"",IF(OR(N(P35)>=说明!$B$5,N(O35)>=说明!$B$6),"大型",IF(OR(N(P35)>=说明!$B$7,N(O35)>=说明!$B$8),"中型","小型"))) | Z35: 360地图 POI（restapi.map.so.com） | AA35: 中
A36: 35 | B36: 武侯区 | C36: 方圆足球俱乐部(苏宁广场) | D36: 方圆足球俱乐部 | E36: 业余俱乐部 | F36: 待核实（可能为成人业余球队/场地） | G36: 运营中（平台收录） | M36: =IF(L36="","",说明!$B$4-L36) | R36: =IF(AND(P36="",O36=""),"",IF(OR(N(P36)>=说明!$B$5,N(O36)>=说明!$B$6),"大型",IF(OR(N(P36)>=说明!$B$7,N(O36)>=说明!$B$8),"中型","小型"))) | Z36: https://huodong.com/venue/detail/vrjjmc | AA36: 低
A37: 36 | B37: 武侯区 | C37: 方圆足球俱乐部(苏宁广场城市奥特莱斯店) | D37: 方圆足球俱乐部 | E37: 业余俱乐部 | F37: 待核实（可能为成人业余球队/场地） | G37: 运营中（地图收录） | I37: 成都市武侯区天府大道北段8号苏宁广场7F | J37: 13709016394 | M37: =IF(L37="","",说明!$B$4-L37) | R37: =IF(AND(P37="",O37=""),"",IF(OR(N(P37)>=说明!$B$5,N(O37)>=说明!$B$6),"大型",IF(OR(N(P37)>=说明!$B$7,N(O37)>=说明!$B$8),"中型","小型"))) | Z37: 360地图 POI（restapi.map.so.com） | AA37: 中
A38: 37 | B38: 武侯区 | C38: 阿迪达斯20号体育公园 | D38: 20号体育公园 / adidas | E38: 场馆运营方 | F38: 待核实（来源未证实青训业务） | G38: 待核实 | I38: 武侯区江安河生态文化旅游带 | L38: 2023 | M38: =IF(L38="","",说明!$B$4-L38) -> 3 | N38: 2023-03-25开放 | R38: =IF(AND(P38="",O38=""),"",IF(OR(N(P38)>=说明!$B$5,N(O38)>=说明!$B$6),"大型",IF(OR(N(P38)>=说明!$B$7,N(O38)>=说明!$B$8),"中型","小型"))) | S38: 约3万平方米；11人制、8人制场各1块及可持续五人制场 | Z38: https://daoinsights.com/news/adidas-first-sustainable-football-pitch-in-china-unveiled-in-chengdu/ https://www.bangcity.cn/index.php/adidasi20haotiyugongyuanrongchengjiepai-quanguoshougekechixuqiuchangzhengshikaifang | AA38: 低 | AB38: 未找到青训课程直接证据
A39: 38 | B39: 武侯区 | C39: 以恒足球俱乐部（武侯校区） | D39: 以恒足球 | E39: 培训机构 | F39: 待核实（可能为成人业余球队/场地） | G39: 待核实 | M39: =IF(L39="","",说明!$B$4-L39) | Q39: 武侯校区（五人制） | R39: =IF(AND(P39="",O39=""),"",IF(OR(N(P39)>=说明!$B$5,N(O39)>=说明!$B$6),"大型",IF(OR(N(P39)>=说明!$B$7,N(O39)>=说明!$B$8),"中型","小型"))) | Z39: https://huodong.com/venue/detail/eyLei | AA39: 低
A40: 39 | B40: 武侯区 | C40: 湖上体育篮球足球体适能综合馆 | D40: 湖上体育篮球足球体适能综合馆 | E40: 培训机构 | F40: 待核实（可能为成人业余球队/场地） | G40: 运营中（地图收录） | I40: 成都市武侯区紫薇东路70号3楼(神仙树地铁站E口步行230米) | J40: 17358522371 | M40: =IF(L40="","",说明!$B$4-L40) | R40: =IF(AND(P40="",O40=""),"",IF(OR(N(P40)>=说明!$B$5,N(O40)>=说明!$B$6),"大型",IF(OR(N(P40)>=说明!$B$7,N(O40)>=说明!$B$8),"中型","小型"))) | Z40: 360地图 POI（restapi.map.so.com） | AA40: 中
...

Sheet 足球场馆
A1: 序号 | B1: 区（市县） | C1: 场馆名称 | D1: 地址 | E1: 电话 | F1: 来源 | G1: 备注
A2: 1 | B2: 锦江区 | C2: 中锦驿动足球场 | D2: 成都市锦江区静沙北路与静秀路交叉口西北50米 | F2: 360地图 POI（restapi.map.so.com）
A3: 2 | B3: 锦江区 | C3: 众禾双桥子足球公园 | D3: 成都市锦江区双桥子南快速公交站前10米 | F3: 360地图 POI（restapi.map.so.com）
A4: 3 | B4: 锦江区 | C4: 兴城足球公园 | D4: 成都市锦江区百日红中路蓝润V客东都-1期南侧约50米 | E4: 18512871289 | F4: 360地图 POI（restapi.map.so.com）
A5: 4 | B5: 锦江区 | C5: 塔子山九天足球场 | F5: https://huodong.com/venue/detail/gjwsre
A6: 5 | B6: 锦江区 | C6: 天际线麒志体育足球公园 | F6: https://huodong.com/venue/detail/grroqj
A7: 6 | B7: 锦江区 | C7: 成都兴城邻里足球公园 | F7: https://huodong.com/venue/detail/gasacr
A8: 7 | B8: 锦江区 | C8: 晨辉路公园足球基地 | F8: https://huodong.com/venue/detail/nhqkcg
A9: 8 | B9: 锦江区 | C9: 经天320足球公园 | D9: 成都市锦江区经天西路320号 | F9: 360地图 POI（restapi.map.so.com）
A10: 9 | B10: 锦江区 | C10: 香樟社区足球场 | D10: 成都市锦江区吉树街绿地中心云玺468 | F10: 360地图 POI（restapi.map.so.com）
A11: 10 | B11: 青羊区 | C11: FF足球公园 | F11: https://huodong.com/venue/detail/jjobew
A12: 11 | B12: 青羊区 | C12: WePark玩湃社区智慧足球公园 | F12: https://huodong.com/venue/detail/krvjel
A13: 12 | B13: 青羊区 | C13: 东坡体育公园足球场 | F13: https://huodong.com/venue/detail/lbfbta
A14: 13 | B14: 青羊区 | C14: 大公园-足球场 | D14: 成都市青羊区蔡桥街道光华大道一段1666号 | F14: 360地图 POI（restapi.map.so.com）
A15: 14 | B15: 青羊区 | C15: 康达园足球场 | D15: 成都市青羊区纬八路成飞康达园东侧约60米 | F15: 360地图 POI（restapi.map.so.com）
A16: 15 | B16: 青羊区 | C16: 星工场足球场 | D16: 成都市青羊区金沙街道金鹏街中大君悦金沙北侧 | F16: 360地图 POI（restapi.map.so.com）
A17: 16 | B17: 青羊区 | C17: 青羊区光华大道蔡桥足球场 | D17: 成都市青羊区光华大道二段 | E17: 13558731323 | F17: 360地图 POI（restapi.map.so.com）
A18: 17 | B18: 金牛区 | C18: 五粮液文化体育中心专业足球场 | F18: https://huodong.com/venue/detail/vugjno
A19: 18 | B19: 金牛区 | C19: 兴恒足球公园 | F19: https://huodong.com/venue/detail/twppoa
A20: 19 | B20: 金牛区 | C20: 凤凰山体育公园-户外足球场 | D20: 成都市金牛区天回镇街道荣德路80号 | F20: 360地图 POI（restapi.map.so.com）
A21: 20 | B21: 金牛区 | C21: 凤凰山体育公园专业足球场 | D21: 成都市金牛区天回镇街道范围内 | F21: 360地图 POI（restapi.map.so.com）
A22: 21 | B22: 金牛区 | C22: 凤凰山体育公园户外足球场 | F22: https://huodong.com/venue/detail/bawbsv
A23: 22 | B23: 金牛区 | C23: 成都金沙足球公园 | D23: 成都市金牛区茶店子街道范围内 | F23: 360地图 POI（restapi.map.so.com）
A24: 23 | B24: 金牛区 | C24: 沙河源公园-足球场 | D24: 成都市金牛区九里堤北路88号(沙河源公园) | F24: 360地图 POI（restapi.map.so.com）
A25: 24 | B25: 金牛区 | C25: 羊犀足球场 | D25: 成都市金牛区黄金东一路56号 | E25: 13982252485 | F25: 360地图 POI（restapi.map.so.com）
A26: 25 | B26: 金牛区 | C26: 金牛体育中心-足球场 | D26: 成都市金牛区茶店子街道金牛体育中心 | F26: 360地图 POI（restapi.map.so.com）
A27: 26 | B27: 金牛区 | C27: 金牛体育中心足球场 | F27: https://huodong.com/venue/detail/mjgjso
A28: 27 | B28: 金牛区 | C28: 金牛足球公园 | D28: 成都市金牛区黄金路 | F28: 360地图 POI（restapi.map.so.com）
A29: 28 | B29: 武侯区 | C29: Joma BCN外双楠足球场 | D29: 成都市武侯区吉顺街88号 | E29: 15982055921 | F29: 360地图 POI（restapi.map.so.com）
A30: 29 | B30: 武侯区 | C30: 丽都公园-足球场 | D30: 成都市武侯区丽都路1号附1号 | E30: 13408631001 | F30: 360地图 POI（restapi.map.so.com）
A31: 30 | B31: 武侯区 | C31: 五大花园体育运动公园-五人制足球场 | D31: 成都市武侯区晋吉东二街256号五大花园体育运动公园 | F31: 360地图 POI（restapi.map.so.com）
A32: 31 | B32: 武侯区 | C32: 四川成都足球广场 | D32: 成都市武侯区太平寺西路 | F32: 360地图 POI（restapi.map.so.com）
A33: 32 | B33: 武侯区 | C33: 四川新北足球中心 | F33: https://huodong.com/venue/detail/cixjsi
A34: 33 | B34: 武侯区 | C34: 成都大牛足球公园 | D34: 成都市武侯区武阳大道一段268号西北方向90米 | E34: 19141929971 | F34: 360地图 POI（restapi.map.so.com）
A35: 34 | B35: 武侯区 | C35: 武侯足球公园 | D35: 成都市武侯区潮音路62号 | E35: 028-83384455 | F35: 360地图 POI（restapi.map.so.com）
A36: 35 | B36: 武侯区 | C36: 水韵园综合教育基地足球场 | D36: 成都市武侯区金花桥街道映月西街映月颐园17幢正西方向170米 | F36: 360地图 POI（restapi.map.so.com）
A37: 36 | B37: 武侯区 | C37: 润林足球场 | F37: https://huodong.com/venue/detail/yrbrzt
A38: 37 | B38: 武侯区 | C38: 潮音水岸篮球足球场 | F38: https://huodong.com/venue/detail/trxnhl
A39: 38 | B39: 武侯区 | C39: 皇家YS足球场 | D39: 成都市武侯区桂溪街道科华南路和平小区四期(东苑B区西) | F39: 360地图 POI（restapi.map.so.com）
A40: 39 | B40: 武侯区 | C40: 空港足球公园 | D40: 成都市武侯区珠江北路11号成都台双医院附近 | F40: 360地图 POI（restapi.map.so.com）
...

Sheet 锦江区
A1: 序号 | B1: 区（市县） | C1: 机构名称 | D1: 品牌/所属 | E1: 机构类型 | F1: 青训业务 | G1: 运营状态 | H1: 公司/法人名称 | I1: 训练地址 | J1: 联系电话 | K1: 其他联系方式 | L1: 成立年份 | M1: 运营年限（年） | N1: 运营年限说明 | O1: 教练员数量 | P1: 学员数量 | Q1: 校区/场地数 | R1: 规模等级 | S1: 规模说明 | T1: 招生年龄 | U1: 大众点评评分 | V1: 美团评分 | W1: 其他平台评分 | X1: 收费信息 | Y1: 荣誉/资质 | Z1: 信息来源 | AA1: 可信度 | AB1: 待核实/备注
A2: 1 | B2: 锦江区 | C2: 四川省宇晖仁德足球俱乐部（卡尔美·成都仁德足球青训基地） | D2: 仁德足球 | E2: 业余俱乐部 | F2: 已证实（有来源） | G2: 待核实 | H2: 四川省宇晖仁德体育文化传播有限责任公司（关联待确认） | I2: 三环路东一段附近 | J2: +86-15114062861 | K2: 官网 http://www.yhrdty.com | L2: 2015 | M2: =IF(L2="","",说明!$B$4-L2) -> 11 | N2: 公司2015-03-05成立（企查查）；注册资本200万元；法定代表人马明宇 | P2: 200 | Q2: 卡尔美成都仁德足球青训基地；锦江仁德足球主题公园 | R2: =IF(AND(P2="",O2=""),"",IF(OR(N(P2)>=说明!$B$5,N(O2)>=说明!$B$6),"大型",IF(OR(N(P2)>=说明!$B$7,N(O2)>=说明!$B$8),"中型","小型"))) -> 中型 | S2: 向锦江、成华、武侯等区学校派驻教练；长期学员约200名（百度百科，年份未注明）；拥有14块标准场地（四川省体育局2020年报道） | T2: 4–18岁 | Y2: 2018雪佛兰全国少儿足球冠军赛成都赛区冠军 | Z2: http://www.yhrdty.com/index.php?m=content&c=index&a=lists&catid=19 https://www.thecfa.cn/cgzq/20190114/26088.html 360地图 POI（restapi.map.so.com） https://huodong.com/venue/detail/tktmlk https://m.qcc.com/firm/3bac3d95ecf684438bd98491320d4a5c.html https://tyj.sc.gov.cn/sctyj/TYaddN/2020/9/14/9855f7280b6649d3bcbf0dd0560f9629.shtml https://baike.baidu.com/item/%E5%9B%9B%E5%B7%9D%E5%AE%87%E6%99%96%E4%BB%81%E5%BE%B7%E8%B6%B3%E7%90%83%E4%BF%B1%E4%B9%90%E9%83%A8/64016151 | AA2: 中 | AB2: 所在区为推断
A3: 2 | B3: 锦江区 | C3: 之己体育迈浪足球学院（锦江店） | D3: 之己体育 / 迈浪足球 | E3: 培训机构 | F3: 已证实（有来源） | G3: 待核实 | I3: 锦江区动感熊猫体育公园内 | J3: 18980068009 | M3: =IF(L3="","",说明!$B$4-L3) | Q3: 锦江店 | R3: =IF(AND(P3="",O3=""),"",IF(OR(N(P3)>=说明!$B$5,N(O3)>=说明!$B$6),"大型",IF(OR(N(P3)>=说明!$B$7,N(O3)>=说明!$B$8),"中型","小型"))) | S3: 5人制、7人制人造草场地 | Z3: https://huodong.com/venue/detail/eyLaq https://huodong.com/venue/detail/qhispx | AA3: 低
A4: 3 | B4: 锦江区 | C4: 索福德青少儿快乐足球培训 | D4: 索福德 | E4: 培训机构 | F4: 已证实（有来源） | G4: 待核实 | I4: 锦江区晨辉西路56号足球公园园区内 | K4: 网站 soccerworld.cn | M4: =IF(L4="","",说明!$B$4-L4) | Q4: 锦江区晨辉西路56号足球公园园区内配套1号办公房屋 | R4: =IF(AND(P4="",O4=""),"",IF(OR(N(P4)>=说明!$B$5,N(O4)>=说明!$B$6),"大型",IF(OR(N(P4)>=说明!$B$7,N(O4)>=说明!$B$8),"中型","小型"))) | W4: 3.0（教育宝（口碑值）） | Z4: https://cd.jiaoyubao.cn/zuqiu/ https://s.jiaoyubao.cn/do/?c=cd&classename=qiulei&k=%E5%B0%91%E5%84%BF | AA4: 低
A5: 4 | B5: 锦江区 | C5: 大牛青少年足球俱乐部 | D5: 大牛青少年足球俱乐部 | E5: 业余俱乐部 | F5: 名称显示青少年业务（待核实） | G5: 运营中（平台收录） | M5: =IF(L5="","",说明!$B$4-L5) | R5: =IF(AND(P5="",O5=""),"",IF(OR(N(P5)>=说明!$B$5,N(O5)>=说明!$B$6),"大型",IF(OR(N(P5)>=说明!$B$7,N(O5)>=说明!$B$8),"中型","小型"))) | Z5: https://huodong.com/venue/detail/yqnohb | AA5: 低
A6: 5 | B6: 锦江区 | C6: 圣斯顿足球俱乐部 | D6: 圣斯顿足球俱乐部 | E6: 业余俱乐部 | F6: 待核实（可能为成人业余球队/场地） | G6: 运营中（平台收录） | M6: =IF(L6="","",说明!$B$4-L6) | R6: =IF(AND(P6="",O6=""),"",IF(OR(N(P6)>=说明!$B$5,N(O6)>=说明!$B$6),"大型",IF(OR(N(P6)>=说明!$B$7,N(O6)>=说明!$B$8),"中型","小型"))) | Z6: https://huodong.com/venue/detail/zbwuqj | AA6: 低
A7: 6 | B7: 锦江区 | C7: 天际线足球俱乐部 | D7: 天际线足球俱乐部 | E7: 业余俱乐部 | F7: 待核实（可能为成人业余球队/场地） | G7: 运营中（地图收录） | I7: 成都市锦江区琉新路301号 | J7: 18628004621 | M7: =IF(L7="","",说明!$B$4-L7) | R7: =IF(AND(P7="",O7=""),"",IF(OR(N(P7)>=说明!$B$5,N(O7)>=说明!$B$6),"大型",IF(OR(N(P7)>=说明!$B$7,N(O7)>=说明!$B$8),"中型","小型"))) | Z7: 360地图 POI（restapi.map.so.com） | AA7: 中
A8: 7 | B8: 锦江区 | C8: 跃九天足球俱乐部 | D8: 跃九天足球俱乐部 | E8: 业余俱乐部 | F8: 待核实（可能为成人业余球队/场地） | G8: 运营中（平台收录） | M8: =IF(L8="","",说明!$B$4-L8) | R8: =IF(AND(P8="",O8=""),"",IF(OR(N(P8)>=说明!$B$5,N(O8)>=说明!$B$6),"大型",IF(OR(N(P8)>=说明!$B$7,N(O8)>=说明!$B$8),"中型","小型"))) | Z8: https://huodong.com/venue/detail/rdcpde | AA8: 低
A9: 8 | B9: 锦江区 | C9: 众禾足球俱乐部 | D9: 众禾足球 | E9: 培训机构 | F9: 待核实（来源未证实青训业务） | G9: 待核实 | I9: 锦江区 众禾双桥子足球公园（环球汇·天誉）；另见静思南巷与中环路锦绣大道段交叉口 | M9: =IF(L9="","",说明!$B$4-L9) | R9: =IF(AND(P9="",O9=""),"",IF(OR(N(P9)>=说明!$B$5,N(O9)>=说明!$B$6),"大型",IF(OR(N(P9)>=说明!$B$7,N(O9)>=说明!$B$8),"中型","小型"))) | S9: 参加第一届中国青少年足球联赛（四川赛区）U9并小组出线；场地地图列有“众禾双桥子足球公园”（关系未证实） | X9: 周末班、寒暑假集训 | Z9: https://huodong.com/venue/detail/eyLaA https://sichuan.scol.com.cn/ggxw/202302/58806642.html https://cd.jiaoyubao.cn/zuqiu/dt_z1910.html | AA9: 中 | AB9: 教育宝：暂无评分
A10: 9 | B10: 锦江区 | C10: 传奇足球梦工场 | D10: 传奇足球梦工场 | E10: 培训机构 | F10: 待核实（可能为成人业余球队/场地） | G10: 运营中（地图收录） | I10: 成都市锦江区桦彩路89号 | J10: 028-61112170 | M10: =IF(L10="","",说明!$B$4-L10) | R10: =IF(AND(P10="",O10=""),"",IF(OR(N(P10)>=说明!$B$5,N(O10)>=说明!$B$6),"大型",IF(OR(N(P10)>=说明!$B$7,N(O10)>=说明!$B$8),"中型","小型"))) | Z10: 360地图 POI（restapi.map.so.com） | AA10: 中
A11: 10 | B11: 锦江区 | C11: 绿轴兴城足球公园(训练基地) | D11: 绿轴兴城足球公园 | E11: 职业俱乐部青训 | F11: 待核实（可能为成人业余球队/场地） | G11: 运营中（地图收录） | I11: 成都市锦江区首开龙湖天璞东门东北 | J11: 18512871289 | M11: =IF(L11="","",说明!$B$4-L11) | R11: =IF(AND(P11="",O11=""),"",IF(OR(N(P11)>=说明!$B$5,N(O11)>=说明!$B$6),"大型",IF(OR(N(P11)>=说明!$B$7,N(O11)>=说明!$B$8),"中型","小型"))) | Z11: 360地图 POI（restapi.map.so.com） | AA11: 中 | AB11: 成都蓉城足球俱乐部训练基地（地图名称），是否对外开设青少年课程未知

Sheet 青羊区
A1: 序号 | B1: 区（市县） | C1: 机构名称 | D1: 品牌/所属 | E1: 机构类型 | F1: 青训业务 | G1: 运营状态 | H1: 公司/法人名称 | I1: 训练地址 | J1: 联系电话 | K1: 其他联系方式 | L1: 成立年份 | M1: 运营年限（年） | N1: 运营年限说明 | O1: 教练员数量 | P1: 学员数量 | Q1: 校区/场地数 | R1: 规模等级 | S1: 规模说明 | T1: 招生年龄 | U1: 大众点评评分 | V1: 美团评分 | W1: 其他平台评分 | X1: 收费信息 | Y1: 荣誉/资质 | Z1: 信息来源 | AA1: 可信度 | AB1: 待核实/备注
A2: 1 | B2: 青羊区 | C2: 皇家贝里斯足球俱乐部（皇贝青训） | D2: 皇贝 | E2: 业余俱乐部 | F2: 已证实（有来源） | G2: 待核实 | I2: 青羊区贝森北路西村大院 | J2: 18080802014 | L2: 2013 | M2: =IF(L2="","",说明!$B$4-L2) -> 13 | N2: 百科称2013年底创立（另说2014年）；运营公司2016年5月成立 | P2: 5000 | Q2: 西村、光华、清波、桂溪、晨辉 5个校区（百度百科）；青羊区贝森北路1号西村大院 | R2: =IF(AND(P2="",O2=""),"",IF(OR(N(P2)>=说明!$B$5,N(O2)>=说明!$B$6),"大型",IF(OR(N(P2)>=说明!$B$7,N(O2)>=说明!$B$8),"中型","小型"))) -> 大型 | S2: 多支6–12岁梯队及兴趣班；累计学员5000余名（百度百科，2025）；约2017年调查：教练10余名 | T2: 6–12岁梯队 | X2: 较早调查：寒假班1280元（年份未标注） | Y2: 据称2019年获中国足协“全国社会足球品牌青训机构”认定（四川唯一）；青训总教练持亚足联A级；青训总教练张林海（原成都五牛主帅） | Z2: https://www.sohu.com/a/338252396_120288288 https://baike.baidu.com/item/%E7%9A%87%E5%AE%B6%E8%B4%9D%E9%87%8C%E6%96%AF%E8%B6%B3%E7%90%83%E4%BF%B1%E4%B9%90%E9%83%A8/16686556 https://m.dongqiudi.com/article/2144123.html 360地图 POI（restapi.map.so.com） http://www.dianping.com/shop/25035403/photos?pg=17 | AA2: 中 | AB2: 有门店页（西村校区），评分未显示
A3: 2 | B3: 青羊区 | C3: FF体育公园（FF足球公园 · 成都足协青少年足球培训中心） | D3: FF体育公园 / 成都足协 | E3: 场馆运营方 | F3: 已证实（有来源） | G3: 运营中 | I3: 成都市青羊区光华大道一段（万家湾公交总站旁） | J3: 028-86743798 | K3: 电话见中国足协官网成都青训中心页面 | M3: =IF(L3="","",说明!$B$4-L3) | Q3: 地图收录：FF足球公园卡丁车俱乐部（青羊区）成都市青羊区蔡桥街道光华8线与成飞大道交汇处万家福地西南角；地图收录：国家青少年足球训练中心（青羊区）成都市青羊区光华南三路88号正西方向180米 | R3: =IF(AND(P3="",O3=""),"",IF(OR(N(P3)>=说明!$B$5,N(O3)>=说明!$B$6),"大型",IF(OR(N(P3)>=说明!$B$7,N(O3)>=说明!$B$8),"中型","小型"))) | S3: 约80亩、投资约1.3亿元；5块五人制、4块八人制、2块十一人制场地；成都足协挂牌青少年足球培训中心、足球重点项目训练基地 | Y3: 中国足协2026年确定成都为大区青训中心（13–15岁，覆盖西南）；拉玛足球在此设校区 | Z3: https://www.thecfa.cn/qxunzx/20180903/24556.html https://m.dongqiudi.com/article/1654210.html https://sports.sina.cn/2026-08-18/detail-ininswmx7436499.d.html?vt=4 360地图 POI（restapi.map.so.com） | AA3: 中 | AB3: 电话为中国足协页面所列青训中心电话，数据时间较早；地图另列名称：国家青少年足球训练中心（青羊区）
A4: 3 | B4: 青羊区 | C4: 拉玛足球 · 青羊区校区（优品道、FF体育公园） | D4: 拉玛足球 | E4: 培训机构 | F4: 已证实（有来源） | G4: 待核实 | I4: 优品道：青羊大道99号优品广场；FF体育公园：光华大道一段 | M4: =IF(L4="","",说明!$B$4-L4) | Q4: 地图收录：成都拉玛足球俱乐部（青羊区）成都市青羊区青羊大道99号附1优品道广场4F | R4: =IF(AND(P4="",O4=""),"",IF(OR(N(P4)>=说明!$B$5,N(O4)>=说明!$B$6),"大型",IF(OR(N(P4)>=说明!$B$7,N(O4)>=说明!$B$8),"中型","小型"))) | Z4: https://m.youkee.com/xuexiao/lmzq_xiaoqu.html 360地图 POI（restapi.map.so.com） | AA4: 低
A5: 4 | B5: 青羊区 | C5: 花香青少年足球（青羊校区） | D5: 花香 | E5: 培训机构 | F5: 已证实（有来源） | G5: 风险：现状未知 | I5: 青羊区蜀辉路金沙国际商城 | M5: =IF(L5="","",说明!$B$4-L5) | R5: =IF(AND(P5="",O5=""),"",IF(OR(N(P5)>=说明!$B$5,N(O5)>=说明!$B$6),"大型",IF(OR(N(P5)>=说明!$B$7,N(O5)>=说明!$B$8),"中型","小型"))) | T5: 5–14岁 | Z5: https://m.youkee.com/kecheng/11810.html | AA5: 低 | AB5: 品牌母公司2024年北京闭店风波，见“花香盛世体育（品牌）”
A6: 5 | B6: 青羊区 | C6: 中达舒弘青少年足球运动俱乐部(光华校区) | D6: 中达舒弘青少年足球运动俱乐部 | E6: 业余俱乐部 | F6: 名称显示青少年业务（待核实） | G6: 运营中（平台收录） | M6: =IF(L6="","",说明!$B$4-L6) | R6: =IF(AND(P6="",O6=""),"",IF(OR(N(P6)>=说明!$B$5,N(O6)>=说明!$B$6),"大型",IF(OR(N(P6)>=说明!$B$7,N(O6)>=说明!$B$8),"中型","小型"))) | Z6: https://huodong.com/venue/detail/hylemk | AA6: 低
A7: 6 | B7: 青羊区 | C7: 青羊区青少年足球训练基地 | D7: 青羊区青少年足球训练基地 | E7: 培训机构 | F7: 名称显示青少年业务（待核实） | G7: 运营中（平台收录） | M7: =IF(L7="","",说明!$B$4-L7) | R7: =IF(AND(P7="",O7=""),"",IF(OR(N(P7)>=说明!$B$5,N(O7)>=说明!$B$6),"大型",IF(OR(N(P7)>=说明!$B$7,N(O7)>=说明!$B$8),"中型","小型"))) | Z7: https://huodong.com/venue/detail/oqeogw | AA7: 低
A8: 7 | B8: 青羊区 | C8: 99号球会 | D8: 99号球会 | E8: 业余俱乐部 | F8: 待核实（可能为成人业余球队/场地） | G8: 运营中（地图收录） | I8: 成都市青羊区文家街道文家大道 | M8: =IF(L8="","",说明!$B$4-L8) | R8: =IF(AND(P8="",O8=""),"",IF(OR(N(P8)>=说明!$B$5,N(O8)>=说明!$B$6),"大型",IF(OR(N(P8)>=说明!$B$7,N(O8)>=说明!$B$8),"中型","小型"))) | Z8: 360地图 POI（restapi.map.so.com） | AA8: 中
A9: 8 | B9: 青羊区 | C9: 金鹰足球俱乐部 | D9: 金鹰足球俱乐部 | E9: 业余俱乐部 | F9: 待核实（可能为成人业余球队/场地） | G9: 运营中（地图收录） | I9: 成都市青羊区康河街道土龙公路四川商务职业学院东南角 | M9: =IF(L9="","",说明!$B$4-L9) | R9: =IF(AND(P9="",O9=""),"",IF(OR(N(P9)>=说明!$B$5,N(O9)>=说明!$B$6),"大型",IF(OR(N(P9)>=说明!$B$7,N(O9)>=说明!$B$8),"中型","小型"))) | Z9: 360地图 POI（restapi.map.so.com） | AA9: 中
A10: 9 | B10: 青羊区 | C10: 玩湃社区足球公园 | D10: 玩湃社区足球公园 | E10: 场馆运营方 | F10: 待核实（可能为成人业余球队/场地） | G10: 运营中（地图收录） | I10: 成都市青羊区通惠门路37号 | J10: 028-18116599858 | M10: =IF(L10="","",说明!$B$4-L10) | R10: =IF(AND(P10="",O10=""),"",IF(OR(N(P10)>=说明!$B$5,N(O10)>=说明!$B$6),"大型",IF(OR(N(P10)>=说明!$B$7,N(O10)>=说明!$B$8),"中型","小型"))) | S10: 约900㎡，成都首个社区智慧足球公园，设24小时智慧足球课堂 | Z10: 360地图 POI（restapi.map.so.com） https://cbgc.scol.com.cn/news/158341 | AA10: 中

Sheet 金牛区
A1: 序号 | B1: 区（市县） | C1: 机构名称 | D1: 品牌/所属 | E1: 机构类型 | F1: 青训业务 | G1: 运营状态 | H1: 公司/法人名称 | I1: 训练地址 | J1: 联系电话 | K1: 其他联系方式 | L1: 成立年份 | M1: 运营年限（年） | N1: 运营年限说明 | O1: 教练员数量 | P1: 学员数量 | Q1: 校区/场地数 | R1: 规模等级 | S1: 规模说明 | T1: 招生年龄 | U1: 大众点评评分 | V1: 美团评分 | W1: 其他平台评分 | X1: 收费信息 | Y1: 荣誉/资质 | Z1: 信息来源 | AA1: 可信度 | AB1: 待核实/备注
A2: 1 | B2: 金牛区 | C2: 成都大牛体育培训 | D2: 大牛 | E2: 培训机构 | F2: 已证实（有来源） | G2: 待核实 | I2: 成都市金牛区金科苑东街65号1栋5单元1层1号 | M2: =IF(L2="","",说明!$B$4-L2) | R2: =IF(AND(P2="",O2=""),"",IF(OR(N(P2)>=说明!$B$5,N(O2)>=说明!$B$6),"大型",IF(OR(N(P2)>=说明!$B$7,N(O2)>=说明!$B$8),"中型","小型"))) | S2: 教育宝金牛区足球培训列表收录 | Z2: https://cd.jiaoyubao.cn/zuqiu/qu_jinniu.html | AA2: 中 | AB2: 教育宝地址为机构自填，可能已过时
A3: 2 | B3: 金牛区 | C3: 成都杰冠体育培训 | D3: 杰冠 | E3: 培训机构 | F3: 已证实（有来源） | G3: 待核实 | I3: 成都市金牛区天龙大道942号1层 | M3: =IF(L3="","",说明!$B$4-L3) | R3: =IF(AND(P3="",O3=""),"",IF(OR(N(P3)>=说明!$B$5,N(O3)>=说明!$B$6),"大型",IF(OR(N(P3)>=说明!$B$7,N(O3)>=说明!$B$8),"中型","小型"))) | S3: 教育宝金牛区足球培训列表收录 | Z3: https://cd.jiaoyubao.cn/zuqiu/qu_jinniu.html | AA3: 中 | AB3: 教育宝地址为机构自填，可能已过时
A4: 3 | B4: 金牛区 | C4: 拉玛足球 · 花照壁校区 | D4: 拉玛足球 | E4: 培训机构 | F4: 已证实（有来源） | G4: 待核实 | M4: =IF(L4="","",说明!$B$4-L4) | R4: =IF(AND(P4="",O4=""),"",IF(OR(N(P4)>=说明!$B$5,N(O4)>=说明!$B$6),"大型",IF(OR(N(P4)>=说明!$B$7,N(O4)>=说明!$B$8),"中型","小型"))) | Z4: https://m.youkee.com/xiaoqu/7257.html | AA4: 低
A5: 4 | B5: 金牛区 | C5: 金牛区足球协会 | E5: 协会 | F5: 协会（组织/承办青少年赛事） | G5: 待核实 | M5: =IF(L5="","",说明!$B$4-L5) | R5: =IF(AND(P5="",O5=""),"",IF(OR(N(P5)>=说明!$B$5,N(O5)>=说明!$B$6),"大型",IF(OR(N(P5)>=说明!$B$7,N(O5)>=说明!$B$8),"中型","小型"))) | S5: 成都市足协会员协会；未见其直接开展青训的资料。金牛区对社会青训机构实行入库管理和年度星级评定（区校足办负责） | Z5: http://www.lysy90.com/fa/23?local=1 https://www.sport.gov.cn/n20001280/n20745751/n20767239/c21778842/content.html | AA5: 低 | AB5: 金牛区青训机构入库名单值得向区校足办索取
A6: 5 | B6: 金牛区 | C6: 博越足球俱乐部 | D6: 博越足球俱乐部 | E6: 业余俱乐部 | F6: 待核实（可能为成人业余球队/场地） | G6: 运营中（地图收录） | I6: 成都市金牛区金科苑中街与金科苑南街交汇处西南 | M6: =IF(L6="","",说明!$B$4-L6) | R6: =IF(AND(P6="",O6=""),"",IF(OR(N(P6)>=说明!$B$5,N(O6)>=说明!$B$6),"大型",IF(OR(N(P6)>=说明!$B$7,N(O6)>=说明!$B$8),"中型","小型"))) | Z6: 360地图 POI（restapi.map.so.com） | AA6: 中
A7: 6 | B7: 金牛区 | C7: 成都腾飞经典足球俱乐部 | D7: 腾飞经典足球俱乐部 | E7: 业余俱乐部 | F7: 待核实（可能为成人业余球队/场地） | G7: 运营中（平台收录） | M7: =IF(L7="","",说明!$B$4-L7) | R7: =IF(AND(P7="",O7=""),"",IF(OR(N(P7)>=说明!$B$5,N(O7)>=说明!$B$6),"大型",IF(OR(N(P7)>=说明!$B$7,N(O7)>=说明!$B$8),"中型","小型"))) | Z7: https://huodong.com/venue/detail/xcnrnd | AA7: 低

Sheet 武侯区
A1: 序号 | B1: 区（市县） | C1: 机构名称 | D1: 品牌/所属 | E1: 机构类型 | F1: 青训业务 | G1: 运营状态 | H1: 公司/法人名称 | I1: 训练地址 | J1: 联系电话 | K1: 其他联系方式 | L1: 成立年份 | M1: 运营年限（年） | N1: 运营年限说明 | O1: 教练员数量 | P1: 学员数量 | Q1: 校区/场地数 | R1: 规模等级 | S1: 规模说明 | T1: 招生年龄 | U1: 大众点评评分 | V1: 美团评分 | W1: 其他平台评分 | X1: 收费信息 | Y1: 荣誉/资质 | Z1: 信息来源 | AA1: 可信度 | AB1: 待核实/备注
A2: 1 | B2: 武侯区 | C2: 成都贝尔克足球俱乐部 | D2: 贝尔克 | E2: 培训机构 | F2: 已证实（有来源） | G2: 待核实 | L2: 2016 | M2: =IF(L2="","",说明!$B$4-L2) -> 10 | N2: 2016年8月成立（百度百科） | R2: =IF(AND(P2="",O2=""),"",IF(OR(N(P2)>=说明!$B$5,N(O2)>=说明!$B$6),"大型",IF(OR(N(P2)>=说明!$B$7,N(O2)>=说明!$B$8),"中型","小型"))) | S2: 以青少年足球培训为核心的综合素质教育机构，总部在武侯区；百科称教练10余名（含中国足协D级1名）；外籍主教练，称获法国梅斯俱乐部支持 | T2: 4–13岁 | Y2: 华宜天下足球联赛最佳组织奖 | Z2: https://baike.baidu.com/item/%E6%88%90%E9%83%BD%E8%B4%9D%E5%B0%94%E5%85%8B%E8%B6%B3%E7%90%83%E4%BF%B1%E4%B9%90%E9%83%A8/19966520 | AA2: 中
A3: 2 | B3: 武侯区 | C3: 拉玛足球（品牌总部 · 武侯区校区） | D3: 拉玛足球 | E3: 培训机构 | F3: 已证实（有来源） | G3: 运营中（待核实） | I3: 银泰城校区：武侯区益州大道1999号银泰城6楼（总部所在不详，以下为多校区） | J3: 400-666-6886；028-87076722（官网所列）；4006-303-880（聚合平台） | K3: 官网 lamafootball.cn | L3: 2016 | M3: =IF(L3="","",说明!$B$4-L3) -> 10 | N3: 宣传称品牌2016年10月成立 | P3: 550 | Q3: 武侯：银泰城（益州大道1999号6楼）、金楠广场（兆景路199号）、凯德·新南（盛和一路99号）；其他区校区见各区分表 | R3: =IF(AND(P3="",O3=""),"",IF(OR(N(P3)>=说明!$B$5,N(O3)>=说明!$B$6),"大型",IF(OR(N(P3)>=说明!$B$7,N(O3)>=说明!$B$8),"中型","小型"))) -> 大型 | S3: 搜狐较早调查：寒假培训人数由300增至550（年份未标注）；校区数各页不一，一页称8个；聚合平台称员工约50人、办公面积3000㎡（非参保数据） | T3: 4.5–16岁 | Y3: 自述外教来自巴塞罗那；课程分兴趣/提高/精英班 | Z3: https://m.youkee.com/xuexiao/lmzq_xiaoqu.html https://m.youkee.com/xuexiao/lmzq_jianjie.html https://m.sohu.com/n/479553636/?wscrid=95360_1 http://www.lamafootball.cn/nationalCenter/ | AA3: 中 | AB3: 跨武侯/高新/青羊/金牛多区；学员数为某年寒假班人数
A4: 3 | B4: 武侯区 | C4: 胜利联盟菲戈足球学院成都分院 | D4: 胜利联盟/菲戈 | E4: 培训机构 | F4: 已证实（有来源） | G4: 已停业 | I4: 红牌楼某商场顶楼（原址） | M4: =IF(L4="","",说明!$B$4-L4) | R4: =IF(AND(P4="",O4=""),"",IF(OR(N(P4)>=说明!$B$5,N(O4)>=说明!$B$6),"大型",IF(OR(N(P4)>=说明!$B$7,N(O4)>=说明!$B$8),"中型","小型"))) | S4: 2017年报道：停训、人去楼空，家长退费无门 | Z4: https://m.thepaper.cn/wifiKey_detail.jsp?contid=1902798&from=wifiKey https://www.cqcb.com/sports/2017-12-17/600642.html | AA4: 中 | AB4: 保留作风险提示
A5: 4 | B5: 武侯区 | C5: 麒麟小将青训俱乐部 | D5: 麒麟小将青训俱乐部 | E5: 业余俱乐部 | F5: 名称显示青少年业务（待核实） | G5: 运营中（平台收录） | M5: =IF(L5="","",说明!$B$4-L5) | R5: =IF(AND(P5="",O5=""),"",IF(OR(N(P5)>=说明!$B$5,N(O5)>=说明!$B$6),"大型",IF(OR(N(P5)>=说明!$B$7,N(O5)>=说明!$B$8),"中型","小型"))) | Z5: https://huodong.com/venue/detail/otpsba | AA5: 低
A6: 5 | B6: 武侯区 | C6: 斯巴达足球学院(天府四街校区) | D6: 斯巴达足球学院 | E6: 培训机构 | F6: 名称显示青少年业务（待核实） | G6: 运营中（平台收录） | M6: =IF(L6="","",说明!$B$4-L6) | R6: =IF(AND(P6="",O6=""),"",IF(OR(N(P6)>=说明!$B$5,N(O6)>=说明!$B$6),"大型",IF(OR(N(P6)>=说明!$B$7,N(O6)>=说明!$B$8),"中型","小型"))) | Z6: https://huodong.com/venue/detail/xivviu | AA6: 低
A7: 6 | B7: 武侯区 | C7: 909足球俱乐部 | D7: 909足球俱乐部 | E7: 业余俱乐部 | F7: 待核实（可能为成人业余球队/场地） | G7: 运营中（地图收录） | I7: 成都市武侯区东原印长江南侧 | M7: =IF(L7="","",说明!$B$4-L7) | R7: =IF(AND(P7="",O7=""),"",IF(OR(N(P7)>=说明!$B$5,N(O7)>=说明!$B$6),"大型",IF(OR(N(P7)>=说明!$B$7,N(O7)>=说明!$B$8),"中型","小型"))) | Z7: 360地图 POI（restapi.map.so.com） | AA7: 中
A8: 7 | B8: 武侯区 | C8: 富搏足球俱乐部(复城广场店) | D8: 富搏足球俱乐部 | E8: 业余俱乐部 | F8: 待核实（可能为成人业余球队/场地） | G8: 运营中（平台收录） | M8: =IF(L8="","",说明!$B$4-L8) | R8: =IF(AND(P8="",O8=""),"",IF(OR(N(P8)>=说明!$B$5,N(O8)>=说明!$B$6),"大型",IF(OR(N(P8)>=说明!$B$7,N(O8)>=说明!$B$8),"中型","小型"))) | Z8: https://huodong.com/venue/detail/cgbuzm | AA8: 低
A9: 8 | B9: 武侯区 | C9: 富搏足球俱乐部(天府中心店) | D9: 富搏足球俱乐部 | E9: 业余俱乐部 | F9: 待核实（可能为成人业余球队/场地） | G9: 运营中（地图收录） | I9: 成都市武侯区天府一街888号(锦城湖地铁站D口步行160米) | M9: =IF(L9="","",说明!$B$4-L9) | R9: =IF(AND(P9="",O9=""),"",IF(OR(N(P9)>=说明!$B$5,N(O9)>=说明!$B$6),"大型",IF(OR(N(P9)>=说明!$B$7,N(O9)>=说明!$B$8),"中型","小型"))) | Z9: 360地图 POI（restapi.map.so.com） | AA9: 中
A10: 9 | B10: 武侯区 | C10: 成都育英足球俱乐部 | D10: 育英足球俱乐部 | E10: 业余俱乐部 | F10: 待核实（可能为成人业余球队/场地） | G10: 运营中（地图收录） | I10: 成都市武侯区新乐北街10号(四川新北足球中心) | J10: 19828366604 | M10: =IF(L10="","",说明!$B$4-L10) | R10: =IF(AND(P10="",O10=""),"",IF(OR(N(P10)>=说明!$B$5,N(O10)>=说明!$B$6),"大型",IF(OR(N(P10)>=说明!$B$7,N(O10)>=说明!$B$8),"中型","小型"))) | Z10: 360地图 POI（restapi.map.so.com） | AA10: 中
A11: 10 | B11: 武侯区 | C11: 方圆足球俱乐部(苏宁广场) | D11: 方圆足球俱乐部 | E11: 业余俱乐部 | F11: 待核实（可能为成人业余球队/场地） | G11: 运营中（平台收录） | M11: =IF(L11="","",说明!$B$4-L11) | R11: =IF(AND(P11="",O11=""),"",IF(OR(N(P11)>=说明!$B$5,N(O11)>=说明!$B$6),"大型",IF(OR(N(P11)>=说明!$B$7,N(O11)>=说明!$B$8),"中型","小型"))) | Z11: https://huodong.com/venue/detail/vrjjmc | AA11: 低
A12: 11 | B12: 武侯区 | C12: 方圆足球俱乐部(苏宁广场城市奥特莱斯店) | D12: 方圆足球俱乐部 | E12: 业余俱乐部 | F12: 待核实（可能为成人业余球队/场地） | G12: 运营中（地图收录） | I12: 成都市武侯区天府大道北段8号苏宁广场7F | J12: 13709016394 | M12: =IF(L12="","",说明!$B$4-L12) | R12: =IF(AND(P12="",O12=""),"",IF(OR(N(P12)>=说明!$B$5,N(O12)>=说明!$B$6),"大型",IF(OR(N(P12)>=说明!$B$7,N(O12)>=说明!$B$8),"中型","小型"))) | Z12: 360地图 POI（restapi.map.so.com） | AA12: 中
A13: 12 | B13: 武侯区 | C13: 阿迪达斯20号体育公园 | D13: 20号体育公园 / adidas | E13: 场馆运营方 | F13: 待核实（来源未证实青训业务） | G13: 待核实 | I13: 武侯区江安河生态文化旅游带 | L13: 2023 | M13: =IF(L13="","",说明!$B$4-L13) -> 3 | N13: 2023-03-25开放 | R13: =IF(AND(P13="",O13=""),"",IF(OR(N(P13)>=说明!$B$5,N(O13)>=说明!$B$6),"大型",IF(OR(N(P13)>=说明!$B$7,N(O13)>=说明!$B$8),"中型","小型"))) | S13: 约3万平方米；11人制、8人制场各1块及可持续五人制场 | Z13: https://daoinsights.com/news/adidas-first-sustainable-football-pitch-in-china-unveiled-in-chengdu/ https://www.bangcity.cn/index.php/adidasi20haotiyugongyuanrongchengjiepai-quanguoshougekechixuqiuchangzhengshikaifang | AA13: 低 | AB13: 未找到青训课程直接证据
A14: 13 | B14: 武侯区 | C14: 以恒足球俱乐部（武侯校区） | D14: 以恒足球 | E14: 培训机构 | F14: 待核实（可能为成人业余球队/场地） | G14: 待核实 | M14: =IF(L14="","",说明!$B$4-L14) | Q14: 武侯校区（五人制） | R14: =IF(AND(P14="",O14=""),"",IF(OR(N(P14)>=说明!$B$5,N(O14)>=说明!$B$6),"大型",IF(OR(N(P14)>=说明!$B$7,N(O14)>=说明!$B$8),"中型","小型"))) | Z14: https://huodong.com/venue/detail/eyLei | AA14: 低
A15: 14 | B15: 武侯区 | C15: 湖上体育篮球足球体适能综合馆 | D15: 湖上体育篮球足球体适能综合馆 | E15: 培训机构 | F15: 待核实（可能为成人业余球队/场地） | G15: 运营中（地图收录） | I15: 成都市武侯区紫薇东路70号3楼(神仙树地铁站E口步行230米) | J15: 17358522371 | M15: =IF(L15="","",说明!$B$4-L15) | R15: =IF(AND(P15="",O15=""),"",IF(OR(N(P15)>=说明!$B$5,N(O15)>=说明!$B$6),"大型",IF(OR(N(P15)>=说明!$B$7,N(O15)>=说明!$B$8),"中型","小型"))) | Z15: 360地图 POI（restapi.map.so.com） | AA15: 中

Sheet 成华区
A1: 序号 | B1: 区（市县） | C1: 机构名称 | D1: 品牌/所属 | E1: 机构类型 | F1: 青训业务 | G1: 运营状态 | H1: 公司/法人名称 | I1: 训练地址 | J1: 联系电话 | K1: 其他联系方式 | L1: 成立年份 | M1: 运营年限（年） | N1: 运营年限说明 | O1: 教练员数量 | P1: 学员数量 | Q1: 校区/场地数 | R1: 规模等级 | S1: 规模说明 | T1: 招生年龄 | U1: 大众点评评分 | V1: 美团评分 | W1: 其他平台评分 | X1: 收费信息 | Y1: 荣誉/资质 | Z1: 信息来源 | AA1: 可信度 | AB1: 待核实/备注
A2: 1 | B2: 成华区 | C2: 成都翊动足球俱乐部 | D2: 翊动 | E2: 培训机构 | F2: 已证实（有来源） | G2: 待核实 | I2: 成华校区：成华区河北路177号；锦江校区：经天西路320号 | J2: 400-029-0979转56017（平台转接号） | M2: =IF(L2="","",说明!$B$4-L2) | Q2: 成华校区、锦江校区；成华校区：跳蹬河北路177号（百灵鸟仕艾康足球运动中心）；锦江校区：经天西路320号（320经天足球公园） | R2: =IF(AND(P2="",O2=""),"",IF(OR(N(P2)>=说明!$B$5,N(O2)>=说明!$B$6),"大型",IF(OR(N(P2)>=说明!$B$7,N(O2)>=说明!$B$8),"中型","小型"))) | S2: 小班滚动开班；足球训练班、寒暑假集训、特长生集训 | T2: 4-12岁 | W2: 4.0（教育宝） | Z2: https://cd.jiaoyubao.cn/zuqiu/dt_z3488.html https://cd.jiaoyubao.cn/zuqiu/ https://peixun.dzwww.com/cd/edu/j_d29c/m/ | AA2: 中
A3: 2 | B3: 成华区 | C3: 拉玛足球 · 青龙场中心 | D3: 拉玛足球 | E3: 培训机构 | F3: 已证实（有来源） | G3: 待核实 | I3: 成华区昭青南路8号 爱球青龙场五人制足球场 | M3: =IF(L3="","",说明!$B$4-L3) | R3: =IF(AND(P3="",O3=""),"",IF(OR(N(P3)>=说明!$B$5,N(O3)>=说明!$B$6),"大型",IF(OR(N(P3)>=说明!$B$7,N(O3)>=说明!$B$8),"中型","小型"))) | Z3: https://www.jianshu.com/p/b5c1331dfe3e | AA3: 低 | AB3: 来源较旧（约2019年）
A4: 3 | B4: 成华区 | C4: 中达舒弘青少年足球运动俱乐部(驷马桥校区) | D4: 中达舒弘青少年足球运动俱乐部 | E4: 业余俱乐部 | F4: 名称显示青少年业务（待核实） | G4: 运营中（平台收录） | M4: =IF(L4="","",说明!$B$4-L4) | R4: =IF(AND(P4="",O4=""),"",IF(OR(N(P4)>=说明!$B$5,N(O4)>=说明!$B$6),"大型",IF(OR(N(P4)>=说明!$B$7,N(O4)>=说明!$B$8),"中型","小型"))) | Z4: https://huodong.com/venue/detail/qiedwg | AA4: 低
A5: 4 | B5: 成华区 | C5: 成都仕艾康足球俱乐部 | D5: 仕艾康足球俱乐部 | E5: 业余俱乐部 | F5: 待核实（可能为成人业余球队/场地） | G5: 运营中（地图收录） | I5: 成都市成华区跳蹬河街道跳蹬河北路与东秀二路交汇处锦绣东方东侧 | M5: =IF(L5="","",说明!$B$4-L5) | R5: =IF(AND(P5="",O5=""),"",IF(OR(N(P5)>=说明!$B$5,N(O5)>=说明!$B$6),"大型",IF(OR(N(P5)>=说明!$B$7,N(O5)>=说明!$B$8),"中型","小型"))) | Z5: 360地图 POI（restapi.map.so.com） | AA5: 中
A6: 5 | B6: 成华区 | C6: 成都博誉五人制足球俱乐部 | D6: 博誉五人制足球俱乐部 | E6: 业余俱乐部 | F6: 待核实（可能为成人业余球队/场地） | G6: 运营中（地图收录） | I6: 成都市成华区鹤林四路 | J6: 18980005998 | M6: =IF(L6="","",说明!$B$4-L6) | R6: =IF(AND(P6="",O6=""),"",IF(OR(N(P6)>=说明!$B$5,N(O6)>=说明!$B$6),"大型",IF(OR(N(P6)>=说明!$B$7,N(O6)>=说明!$B$8),"中型","小型"))) | Z6: 360地图 POI（restapi.map.so.com） | AA6: 中
A7: 6 | B7: 成华区 | C7: 成都博誉足球俱乐部 | D7: 博誉足球俱乐部 | E7: 业余俱乐部 | F7: 待核实（可能为成人业余球队/场地） | G7: 运营中（地图收录） | I7: 成都市成华区鹤林四路 | J7: 18980005998 | M7: =IF(L7="","",说明!$B$4-L7) | R7: =IF(AND(P7="",O7=""),"",IF(OR(N(P7)>=说明!$B$5,N(O7)>=说明!$B$6),"大型",IF(OR(N(P7)>=说明!$B$7,N(O7)>=说明!$B$8),"中型","小型"))) | Z7: 360地图 POI（restapi.map.so.com） | AA7: 中
A8: 7 | B8: 成华区 | C8: 成都嵿峰足球俱乐部 | D8: 嵿峰足球俱乐部 | E8: 业余俱乐部 | F8: 待核实（可能为成人业余球队/场地） | G8: 运营中（平台收录） | M8: =IF(L8="","",说明!$B$4-L8) | R8: =IF(AND(P8="",O8=""),"",IF(OR(N(P8)>=说明!$B$5,N(O8)>=说明!$B$6),"大型",IF(OR(N(P8)>=说明!$B$7,N(O8)>=说明!$B$8),"中型","小型"))) | Z8: https://huodong.com/venue/detail/hgowpv | AA8: 低
A9: 8 | B9: 成华区 | C9: 成都市蜀龙骁将足球俱乐部 | D9: 蜀龙骁将足球俱乐部 | E9: 业余俱乐部 | F9: 待核实（可能为成人业余球队/场地） | G9: 运营中（平台收录） | M9: =IF(L9="","",说明!$B$4-L9) | R9: =IF(AND(P9="",O9=""),"",IF(OR(N(P9)>=说明!$B$5,N(O9)>=说明!$B$6),"大型",IF(OR(N(P9)>=说明!$B$7,N(O9)>=说明!$B$8),"中型","小型"))) | Z9: https://huodong.com/venue/detail/wnhjry | AA9: 低

Sheet 高新区
A1: 序号 | B1: 区（市县） | C1: 机构名称 | D1: 品牌/所属 | E1: 机构类型 | F1: 青训业务 | G1: 运营状态 | H1: 公司/法人名称 | I1: 训练地址 | J1: 联系电话 | K1: 其他联系方式 | L1: 成立年份 | M1: 运营年限（年） | N1: 运营年限说明 | O1: 教练员数量 | P1: 学员数量 | Q1: 校区/场地数 | R1: 规模等级 | S1: 规模说明 | T1: 招生年龄 | U1: 大众点评评分 | V1: 美团评分 | W1: 其他平台评分 | X1: 收费信息 | Y1: 荣誉/资质 | Z1: 信息来源 | AA1: 可信度 | AB1: 待核实/备注
A2: 1 | B2: 高新区 | C2: 成都汇萃体育培训 | D2: 汇萃体育 | E2: 培训机构 | F2: 已证实（有来源） | G2: 待核实 | H2: 成都汇萃体育文化传播有限公司（教育宝） | I2: 成都高新区天府四街66号2栋3层4号 | M2: =IF(L2="","",说明!$B$4-L2) | R2: =IF(AND(P2="",O2=""),"",IF(OR(N(P2)>=说明!$B$5,N(O2)>=说明!$B$6),"大型",IF(OR(N(P2)>=说明!$B$7,N(O2)>=说明!$B$8),"中型","小型"))) | Z2: https://cd.jiaoyubao.cn/zuqiu/ | AA2: 低 | AB2: 教育宝：暂无评分
A3: 2 | B3: 高新区 | C3: 成都猎豹足球培训 | D3: 猎豹足球 | E3: 培训机构 | F3: 已证实（有来源） | G3: 现状未知 | I3: 成都高新区大源体育公园内18号 | M3: =IF(L3="","",说明!$B$4-L3) | Q3: 地图收录：成都高新区猎豹足球俱乐部（武侯区）成都市武侯区桂溪街道大源南二街与昆华路交汇处桂溪安全文化公园；成都高新区大源体育公园（昆华路919号） | R3: =IF(AND(P3="",O3=""),"",IF(OR(N(P3)>=说明!$B$5,N(O3)>=说明!$B$6),"大型",IF(OR(N(P3)>=说明!$B$7,N(O3)>=说明!$B$8),"中型","小型"))) | S3: 2块五人制场地（本地宝，未注明日期） | Y3: 川足名宿姚夏创办；2016岁月明星杯全国青少年邀请赛参赛 | Z3: https://cd.jiaoyubao.cn/zuqiu/ 360地图 POI（restapi.map.so.com） https://m.cd.bendibao.com/tour/72476_5.shtm https://m.thepaper.cn/newsDetail_forward_3975372 | AA3: 低
A4: 3 | B4: 高新区 | C4: 拉玛足球 · 桂溪（UPARK）/南城荟校区 | D4: 拉玛足球 | E4: 培训机构 | F4: 已证实（有来源） | G4: 待核实 | I4: 桂溪：盛邦街富华北路666号UPARK公园足球场；南城荟：万象北路138号（另一页写武侯区成汉中路181号） | M4: =IF(L4="","",说明!$B$4-L4) | R4: =IF(AND(P4="",O4=""),"",IF(OR(N(P4)>=说明!$B$5,N(O4)>=说明!$B$6),"大型",IF(OR(N(P4)>=说明!$B$7,N(O4)>=说明!$B$8),"中型","小型"))) | Z4: https://m.youkee.com/xuexiao/lmzq_xiaoqu.html https://m.youkee.com/xiaoqu/7252.html | AA4: 低
A5: 4 | B5: 高新区 | C5: 沸点足球俱乐部（高新校区） | D5: 沸点足球 | E5: 培训机构 | F5: 已证实（有来源） | G5: 待核实 | M5: =IF(L5="","",说明!$B$4-L5) | Q5: 高新校区 | R5: =IF(AND(P5="",O5=""),"",IF(OR(N(P5)>=说明!$B$5,N(O5)>=说明!$B$6),"大型",IF(OR(N(P5)>=说明!$B$7,N(O5)>=说明!$B$8),"中型","小型"))) | Z5: https://huodong.com/venue/detail/ey7bj https://huodong.com/venue/detail/egwocd | AA5: 低 | AB5: 另一来源标注在武侯区神仙树南路；地图收录地址在武侯区一侧
A6: 5 | B6: 高新区 | C6: 拜仁成都足球学校（规划） | D6: FC Bayern | E6: 海外青训分校 | F6: 待核实（来源未证实青训业务） | G6: 规划（未见运营） | M6: =IF(L6="","",说明!$B$4-L6) | N6: 约2018年报道的规划项目 | R6: =IF(AND(P6="",O6=""),"",IF(OR(N(P6)>=说明!$B$5,N(O6)>=说明!$B$6),"大型",IF(OR(N(P6)>=说明!$B$7,N(O6)>=说明!$B$8),"中型","小型"))) | T6: 幼儿园至高中（规划） | Z6: https://www.thepaper.cn/newsDetail_forward_2851799 | AA6: 低

Sheet 天府新区
A1: 序号 | B1: 区（市县） | C1: 机构名称 | D1: 品牌/所属 | E1: 机构类型 | F1: 青训业务 | G1: 运营状态 | H1: 公司/法人名称 | I1: 训练地址 | J1: 联系电话 | K1: 其他联系方式 | L1: 成立年份 | M1: 运营年限（年） | N1: 运营年限说明 | O1: 教练员数量 | P1: 学员数量 | Q1: 校区/场地数 | R1: 规模等级 | S1: 规模说明 | T1: 招生年龄 | U1: 大众点评评分 | V1: 美团评分 | W1: 其他平台评分 | X1: 收费信息 | Y1: 荣誉/资质 | Z1: 信息来源 | AA1: 可信度 | AB1: 待核实/备注
A2: 1 | B2: 天府新区 | C2: 20号足球公园（天府公园HI-PARK运动中心） | D2: 20号足球公园（邹侑根） | E2: 场馆运营方 | F2: 已证实（有来源） | G2: 待核实 | I2: 天府公园HI-PARK运动中心内 | L2: 2013 | M2: =IF(L2="","",说明!$B$4-L2) -> 13 | N2: 品牌首店2013年于锦城湖边开业；天府公园店2021-12开业 | R2: =IF(AND(P2="",O2=""),"",IF(OR(N(P2)>=说明!$B$5,N(O2)>=说明!$B$6),"大型",IF(OR(N(P2)>=说明!$B$7,N(O2)>=说明!$B$8),"中型","小型"))) | S2: 8人制场2块、5人制场1块、5人制训练场1块 | Y2: 宣称开展常态化训练教学；“省足协青少年足球发展基地”一说未能证实 | Z2: https://www.sohu.com/a/514268912_670423 https://www.163.com/dy/article/HEDQGE510514OL9V.html | AA2: 中
A3: 2 | B3: 天府新区 | C3: 拉玛足球 · 华阳中心 | D3: 拉玛足球 | E3: 培训机构 | F3: 已证实（有来源） | G3: 待核实 | I3: 华阳观音湾路锦官丽城亲水湾旁 星空5V5滨河足球场 | M3: =IF(L3="","",说明!$B$4-L3) | R3: =IF(AND(P3="",O3=""),"",IF(OR(N(P3)>=说明!$B$5,N(O3)>=说明!$B$6),"大型",IF(OR(N(P3)>=说明!$B$7,N(O3)>=说明!$B$8),"中型","小型"))) | Z3: https://www.jianshu.com/p/b5c1331dfe3e | AA3: 低 | AB3: 来源较旧；华阳片区行政归属以实地为准
